Workbook

Sheet 개요
A1: 데일리 농장 GDD
A2: 홈 카드 왼쪽 한 달 시즌제 농사 게임. 계획 문서 docs/farm-plan.md · 입력 문서 docs/farm-*.md
A4: 읽는 법
A5: 입력 (정한 숫자 · 표) | B5: 파란 글씨 + 연한 노란 바탕. 여기를 고치면 수식이 따라 바뀌어요
A6: 수식 | B6: 검정 글씨. 고치지 마세요
A7: 다른 시트에서 가져온 값 | B7: 초록 글씨
A9: 진행 상황 (계획 문서와 같음)
A10: 항목 | B10: 상태 | C10: 계획 §
A11: NP (버는 쪽) | B11: 확정 | C11: §2
A12: 시즌 · 초기화 | B12: 확정 | C12: §3
A13: 탐험 보상 (리스트 · 히든 · 보물 상자) | B13: 확정 | C13: §4
A14: 농사 · 씨앗 → 작물 · 작물 55종 | B14: 확정 (작물 이름은 Claude 추천, 나중에 시트에서 고침) | C14: §5
A15: 품질 | B15: 확정 | C15: §6
A16: 제작 (강화 39단계) | B16: 확정 (10/5 탐험 강화 · 장신구 착용 추가) | C16: §7
A17: 제작 비용 | B17: 확정 (Claude 추천, 2주 풀업그레이드 기준) | C17: §8
A18: 요리 목록 (100개 · 재료) | B18: 확정 (재료 규칙은 사용자, 목록은 Claude) | C18: §13
A19: 요리하기 · 별 · 판매 값 · 도감 6개 고르기 | B19: 확정 (10/5 사용자, 별 계산식 · 등급 기본 가격은 Claude 추천안 그대로) | C19: §14
A20: 도감 등록 · 갱신 | B20: 확정 (10/5 사용자) | C20: §14
A21: 화폐 · 분해 · 판매 (SP · AP · 돈) | B21: 확정 (10/5 사용자) | C21: §12 · §14
... A26: 장신구 착용 · 잠금 · 가방 | B26: 확정 (10/5 사용자) | C26: §11
A28: 빼기로 한 것
A29: 시즌 작물 품질 ↑↓, 시즌 버프/디버프, 작물을 제작 재료로 쓰기, 요리 먹기(버프), 돈 상점
A31: 알고 두는 빈 곳 (일단 그대로, 만들어 보고 고침)
A32: 15일부터 자재 · 돈을 쓸 곳이 없음 (강화가 14일에 끝남) → 제작 시트 맨 아래
A33: NP는 하루 약 42~68 들어오는데 NP 상점은 하루 최대 24 → 화폐·상점 시트 "하루 NP 남는 양"
A35: 시트
A36: 시트 | B36: 내용
A37: NP·시즌 | B37: NP 버는 값 · 하루/시즌 최대 · 시즌 규칙 (§2 · §3)
A38: 탐험 | B38: 굴림 확률표 · 히든 · 보물 상자 · 하루 기대값 (§4)
A39: 작물 | B39: 씨앗 → 작물 등급 · 수확 개수 · 작물 55종 (이름 고치는 곳) (§5)
A40: 품질표 | B40: 품질 분포 · 그래프 2개 · 정성스레 (§6)
A41: 제작 | B41: 39단계 효과 · 비용(자재 · 고급 자재 · 돈) · 목표일 · 날짜별 검산 (§7 · §8)
A42: 요리·별 | B42: 기본 가격 · 별 배율 · 룰렛 · 도감 개수 · 별 확률 계산기 (§14)
A43: 요리 목록 | B43: 요리 100개 · 재료 · 원래 값 범위 · 재료 이름/등급 확인 (§13)
A44: 화폐·상점 | B44: 분해 값 · 하루 SP/AP · NP 상점 · AP·SP 상점 (§12 · §15)
A45: 장신구 | B45: 줄 수 · 등급 확률 · 옵션 9개 수치 · 착용 · 고대 유물 (§11)

Sheet NP·시즌
A1: NP · 시즌
A2: 계획 §2 · §3. NP 잔액 = 이번 시즌 번 NP(기록에서 매번 계산) + 보물 상자 NP − 쓴 NP
A4: NP 버는 쪽 | B4: NP
A5: 출석 (그날 허브를 열면) | B5: 5
A6: 데일리 성공 | B6: 3
A7: 데일리 실패 · 시간 초과 · 포기 | B7: 2
A9: 게임 | B9: 모드 수
A10: 스도쿠 | B10: 2
A11: 삼각관계 | B11: 2
A12: 워드십 | B12: 3
A13: 흑백 지뢰찾기 | B13: 2
A14: 게임 × 모드 합계 | B14: =SUM(B10:B13) -> 9
A16: 시즌 일수 (가장 긴 달) | B16: 31
A17: 하루 최대 (출석 + 모두 성공) | B17: =B5+B14*B6 -> 32
A18: 시즌 최대 | B18: =B17*B16 -> 992
A19: 하루 보물 상자 NP (탐험 강화 0) | B19: =탐험!$B$53 -> 21.820408
A20: 하루 보물 상자 NP (탐험 강화 2) | B20: =탐험!$D$53 -> 36.367347
A21: NP 상점에서 하루에 쓸 수 있는 최대 | B21: =화폐·상점!$E$34 -> 24
A23: 시즌: 한 달이 한 시즌. 다음 달 1일 06:00 KST에 바뀌고, NP 잔액 · 가방 · 밭 · 강화 · 탐험 · SP · AP · 돈을 전부 초기화
A24: 지난 시즌은 도감 기록(등록 수 0~6 · 별 합 0~18)만 history에 남겨 홈 프로필에 표시
A25: 도감 6개 = 시드 farm:{season}:codex로 요리 100개 중 등급별로 고름 (요리·별 시트). 시즌 내용이 모두에게 같음
A26: 지난 퍼즐 · 자유 연습은 NP에 안 들어감 (원래 기록되지 않음)

Sheet 탐험
A1: 탐험
A2: 계획 §4. 1시간마다 r번 굴림 (r = 기본 + 탐험 강화 단계), 상한 48시간. 굴림 1번 = 히든 1% → 아니면 분류 → 분류 안 아이템 → 개수
A4: 항목 | B4: 값
A5: 1시간마다 굴림 (기본) | B5: 3
A6: 탐험 상한 (시간) | B6: 48
A7: 히든 확률 | B7: 0.01
A8: NP 부스트 배율 | B8: 2
A10: 분류 | B10: 확률
A11: 씨앗 | B11: 0.6
A12: 자재 | B12: 0.35
A13: 장비 | B13: 0.05
A14: 합계 (100%여야 함) | B14: =SUM(B11:B13) -> 1
A16: 분류 | B16: 아이템 | C16: 분류 안 확률 | D16: 개수 최소 | E16: 개수 최대 | F16: 평균 개수 | G16: 굴림 1번에서 나올 확률 | H16: 굴림 1번 기대 개수
A17: 씨앗 | B17: 일반 씨앗 | C17: 0.6 | D17: 3 | E17: 5 | F17: =(D17+E17)/2 -> 4 | G17: =(1-$B$7)*INDEX($B$11:$B$13,MATCH(A17,$A$11:$A$13,0))*C17 -> 0.3564 | H17: =G17*F17 -> 1.4256
A18: 씨앗 | B18: 고급 씨앗 | C18: 0.3 | D18: 3 | E18: 5 | F18: =(D18+E18)/2 -> 4 | G18: =(1-$B$7)*INDEX($B$11:$B$13,MATCH(A18,$A$11:$A$13,0))*C18 -> 0.1782 | H18: =G18*F18 -> 0.7128
A19: 씨앗 | B19: 희귀 씨앗 | C19: 0.09 | D19: 2 | E19: 4 | F19: =(D19+E19)/2 -> 3 | G19: =(1-$B$7)*INDEX($B$11:$B$13,MATCH(A19,$A$11:$A$13,0))*C19 -> 0.05346 | H19: =G19*F19 -> 0.16038
A20: 씨앗 | B20: 전설 씨앗 | C20: 0.01 | D20: 1 | E20: 2 | F20: =(D20+E20)/2 -> 1.5 | G20: =(1-$B$7)*INDEX($B$11:$B$13,MATCH(A20,$A$11:$A$13,0))*C20 -> 0.00594 | H20: =G20*F20 -> 0.00891
A21: 자재 | B21: 자재 | C21: 0.8 | D21: 3 | E21: 5 | F21: =(D21+E21)/2 -> 4 | G21: =(1-$B$7)*INDEX($B$11:$B$13,MATCH(A21,$A$11:$A$13,0))*C21 -> 0.2772 | H21: =G21*F21 -> 1.1088
A22: 자재 | B22: 고급 자재 | C22: 0.2 | D22: 2 | E22: 3 | F22: =(D22+E22)/2 -> 2.5 | G22: =(1-$B$7)*INDEX($B$11:$B$13,MATCH(A22,$A$11:$A$13,0))*C22 -> 0.0693 | H22: =G22*F22 -> 0.17325
A23: 장비 | B23: 장신구 | C23: 1 | D23: 1 | E23: 1 | F23: =(D23+E23)/2 -> 1 | G23: =(1-$B$7)*INDEX($B$11:$B$13,MATCH(A23,$A$11:$A$13,0))*C23 -> 0.0495 | H23: =G23*F23 -> 0.0495
A24: 분류마다 합계 (각 100%여야 함) | C24: =SUMIF(A17:A23,"씨앗",C17:C23)&" · "&SUMIF(A17:A23,"자재",C17:C23)&" · "&SUMIF(A17:A23,"장비",C17:C23) -> 1 · 1 · 1
A26: 히든 아이템 | B26: 히든 안 확률 | C26: 굴림 1번에서 나올 확률 | D26: 열면
A27: 보물 상자 | B27: 0.5 | C27: =$B$7*B27 -> 0.005 | D27: 아래 표에서 1줄
A28: 고대 유물 | B28: 0.5 | C28: =$B$7*B28 -> 0.005 | D28: 옵션 2줄 장신구 1개, 그중 1줄은 전설 (장신구 시트)
A30: 보물 상자 결과 | B30: 확률 | C30: NP | D30: 전설 씨앗 | E30: 고급 자재 | F30: 즉시 완료권 | G30: 보물 상자
A31: 100 NP | B31: 0.198 | C31: 100 | D31: 0 | E31: 0 | F31: 0 | G31: 0
A32: 200 NP | B32: 0.198 | C32: 200 | D32: 0 | E32: 0 | F32: 0 | G32: 0
A33: 전설 씨앗 ×3 | B33: 0.198 | C33: 0 | D33: 3 | E33: 0 | F33: 0 | G33: 0
A34: 고급 자재 ×50 | B34: 0.198 | C34: 0 | D34: 0 | E34: 50 | F34: 0 | G34: 0
A35: 즉시 완료권 ×10 | B35: 0.198 | C35: 0 | D35: 0 | E35: 0 | F35: 10 | G35: 0
A36: 보물 상자 ×2 | B36: 0.01 | C36: 0 | D36: 0 | E36: 0 | F36: 0 | G36: 2
A37: 합계 확률 | B37: =SUM(B31:B36) -> 1
A38: 상자 1개를 열면 여는 횟수 (×2 연쇄 포함) | B38: =1/(1-SUMPRODUCT(B31:B36,G31:G36)) -> 1.0204082
A39: 상자 1개 평균 | C39: =$B$38*SUMPRODUCT($B$31:$B$36,C31:C36) -> 60.612245 | D39: =$B$38*SUMPRODUCT($B$31:$B$36,D31:D36) -> 0.60612245 | E39: =$B$38*SUMPRODUCT($B$31:$B$36,E31:E36) -> 10.102041 | F39: =$B$38*SUMPRODUCT($B$31:$B$36,F31:F36) -> 2.0204082
A41: 하루 기대값 | B41: 탐험 강화 0 | C41: 탐험 강화 1 | D41: 탐험 강화 2
A42: 탐험 강화 단계 | B42: 0 | C42: 1 | D42: 2
A43: 하루 굴림 (48시간 안에 한 번씩 받으면) | B43: =24*($B$5+B42) -> 72 | C43: =24*($B$5+C42) -> 96 | D43: =24*($B$5+D42) -> 120
A44: 일반 씨앗 | B44: =B$43*$H$17 -> 102.6432 | C44: =C$43*$H$17 -> 136.8576 | D44: =D$43*$H$17 -> 171.072
A45: 고급 씨앗 | B45: =B$43*$H$18 -> 51.3216 | C45: =C$43*$H$18 -> 68.4288 | D45: =D$43*$H$18 -> 85.536
A46: 희귀 씨앗 | B46: =B$43*$H$19 -> 11.54736 | C46: =C$43*$H$19 -> 15.39648 | D46: =D$43*$H$19 -> 19.2456
...

Sheet 작물
A1: 작물
A2: 계획 §5. 모든 씨앗은 8시간 뒤 수확. 작물 등급은 심는 순간 굴림. 이름 칸을 고치면 요리 목록의 재료 이름도 같이 고쳐 주세요
A4: 씨앗 \ 작물 | B4: 일반 | C4: 고급 | D4: 희귀 | E4: 전설 | F4: 합계
A5: 일반 씨앗 | B5: 0.7 | C5: 0.25 | D5: 0.05 | E5: 0 | F5: =SUM(B5:E5) -> 1
A6: 고급 씨앗 | B6: 0.3 | C6: 0.5 | D6: 0.2 | E6: 0 | F6: =SUM(B6:E6) -> 1
A7: 희귀 씨앗 | B7: 0.05 | C7: 0.4 | D7: 0.5 | E7: 0.05 | F7: =SUM(B7:E7) -> 1
A8: 전설 씨앗 | B8: 0 | C8: 0 | D8: 0.5 | E8: 0.5 | F8: =SUM(B8:E8) -> 1
A10: 작물 등급 | B10: 수확 최소 | C10: 수확 최대 | D10: 작물 수
A11: 일반 | B11: 2 | C11: 3 | D11: =COUNTIF($B$17:$B$71,A11) -> 20
A12: 고급 | B12: 2 | C12: 3 | D12: =COUNTIF($B$17:$B$71,A12) -> 20
A13: 희귀 | B13: 1 | C13: 2 | D13: =COUNTIF($B$17:$B$71,A13) -> 10
A14: 전설 | B14: 1 | C14: 1 | D14: =COUNTIF($B$17:$B$71,A14) -> 5
A16: # | B16: 등급 | C16: 작물 (이름) | D16: 수확 최소 | E16: 수확 최대 | F16: 일반 씨앗 → 이 작물 | G16: 고급 씨앗 → | H16: 희귀 씨앗 → | I16: 전설 씨앗 → | J16: 쓰이는 요리 수
A17: 1 | B17: 일반 | C17: 감자 | D17: =INDEX($B$11:$B$14,MATCH(B17,$A$11:$A$14,0)) -> 2 | E17: =INDEX($C$11:$C$14,MATCH(B17,$A$11:$A$14,0)) -> 3 | F17: =INDEX($B$5:$E$5,MATCH($B17,$B$4:$E$4,0))/INDEX($D$11:$D$14,MATCH($B17,$A$11:$A$14,0)) -> 0.035 | G17: =INDEX($B$6:$E$6,MATCH($B17,$B$4:$E$4,0))/INDEX($D$11:$D$14,MATCH($B17,$A$11:$A$14,0)) -> 0.015 | H17: =INDEX($B$7:$E$7,MATCH($B17,$B$4:$E$4,0))/INDEX($D$11:$D$14,MATCH($B17,$A$11:$A$14,0)) -> 0.0025 | I17: =INDEX($B$8:$E$8,MATCH($B17,$B$4:$E$4,0))/INDEX($D$11:$D$14,MATCH($B17,$A$11:$A$14,0)) -> 0 | J17: =COUNTIF('요리 목록'!$D$5:$D$104,C17)+COUNTIF('요리 목록'!$F$5:$F$104,C17)+COUNTIF('요리 목록'!$H$5:$H$104,C17) -> 9
A18: 2 | B18: 일반 | C18: 고구마 | D18: =INDEX($B$11:$B$14,MATCH(B18,$A$11:$A$14,0)) -> 2 | E18: =INDEX($C$11:$C$14,MATCH(B18,$A$11:$A$14,0)) -> 3 | F18: =INDEX($B$5:$E$5,MATCH($B18,$B$4:$E$4,0))/INDEX($D$11:$D$14,MATCH($B18,$A$11:$A$14,0)) -> 0.035 | G18: =INDEX($B$6:$E$6,MATCH($B18,$B$4:$E$4,0))/INDEX($D$11:$D$14,MATCH($B18,$A$11:$A$14,0)) -> 0.015 | H18: =INDEX($B$7:$E$7,MATCH($B18,$B$4:$E$4,0))/INDEX($D$11:$D$14,MATCH($B18,$A$11:$A$14,0)) -> 0.0025 | I18: =INDEX($B$8:$E$8,MATCH($B18,$B$4:$E$4,0))/INDEX($D$11:$D$14,MATCH($B18,$A$11:$A$14,0)) -> 0 | J18: =COUNTIF('요리 목록'!$D$5:$D$104,C18)+COUNTIF('요리 목록'!$F$5:$F$104,C18)+COUNTIF('요리 목록'!$H$5:$H$104,C18) -> 4
A19: 3 | B19: 일반 | C19: 당근 | D19: =INDEX($B$11:$B$14,MATCH(B19,$A$11:$A$14,0)) -> 2 | E19: =INDEX($C$11:$C$14,MATCH(B19,$A$11:$A$14,0)) -> 3 | F19: =INDEX($B$5:$E$5,MATCH($B19,$B$4:$E$4,0))/INDEX($D$11:$D$14,MATCH($B19,$A$11:$A$14,0)) -> 0.035 | G19: =INDEX($B$6:$E$6,MATCH($B19,$B$4:$E$4,0))/INDEX($D$11:$D$14,MATCH($B19,$A$11:$A$14,0)) -> 0.015 | H19: =INDEX($B$7:$E$7,MATCH($B19,$B$4:$E$4,0))/INDEX($D$11:$D$14,MATCH($B19,$A$11:$A$14,0)) -> 0.0025 | I19: =INDEX($B$8:$E$8,MATCH($B19,$B$4:$E$4,0))/INDEX($D$11:$D$14,MATCH($B19,$A$11:$A$14,0)) -> 0 | J19: =COUNTIF('요리 목록'!$D$5:$D$104,C19)+COUNTIF('요리 목록'!$F$5:$F$104,C19)+COUNTIF('요리 목록'!$H$5:$H$104,C19) -> 8
A20: 4 | B20: 일반 | C20: 무 | D20: =INDEX($B$11:$B$14,MATCH(B20,$A$11:$A$14,0)) -> 2 | E20: =INDEX($C$11:$C$14,MATCH(B20,$A$11:$A$14,0)) -> 3 | F20: =INDEX($B$5:$E$5,MATCH($B20,$B$4:$E$4,0))/INDEX($D$11:$D$14,MATCH($B20,$A$11:$A$14,0)) -> 0.035 | G20: =INDEX($B$6:$E$6,MATCH($B20,$B$4:$E$4,0))/INDEX($D$11:$D$14,MATCH($B20,$A$11:$A$14,0)) -> 0.015 | H20: =INDEX($B$7:$E$7,MATCH($B20,$B$4:$E$4,0))/INDEX($D$11:$D$14,MATCH($B20,$A$11:$A$14,0)) -> 0.0025 | I20: =INDEX($B$8:$E$8,MATCH($B20,$B$4:$E$4,0))/INDEX($D$11:$D$14,MATCH($B20,$A$11:$A$14,0)) -> 0 | J20: =COUNTIF('요리 목록'!$D$5:$D$104,C20)+COUNTIF('요리 목록'!$F$5:$F$104,C20)+COUNTIF('요리 목록'!$H$5:$H$104,C20) -> 2
A21: 5 | B21: 일반 | C21: 양파 | D21: =INDEX($B$11:$B$14,MATCH(B21,$A$11:$A$14,0)) -> 2 | E21: =INDEX($C$11:$C$14,MATCH(B21,$A$11:$A$14,0)) -> 3 | F21: =INDEX($B$5:$E$5,MATCH($B21,$B$4:$E$4,0))/INDEX($D$11:$D$14,MATCH($B21,$A$11:$A$14,0)) -> 0.035 | G21: =INDEX($B$6:$E$6,MATCH($B21,$B$4:$E$4,0))/INDEX($D$11:$D$14,MATCH($B21,$A$11:$A$14,0)) -> 0.015 | H21: =INDEX($B$7:$E$7,MATCH($B21,$B$4:$E$4,0))/INDEX($D$11:$D$14,MATCH($B21,$A$11:$A$14,0)) -> 0.0025 | I21: =INDEX($B$8:$E$8,MATCH($B21,$B$4:$E$4,0))/INDEX($D$11:$D$14,MATCH($B21,$A$11:$A$14,0)) -> 0 | J21: =COUNTIF('요리 목록'!$D$5:$D$104,C21)+COUNTIF('요리 목록'!$F$5:$F$104,C21)+COUNTIF('요리 목록'!$H$5:$H$104,C21) -> 11
A22: 6 | B22: 일반 | C22: 대파 | D22: =INDEX($B$11:$B$14,MATCH(B22,$A$11:$A$14,0)) -> 2 | E22: =INDEX($C$11:$C$14,MATCH(B22,$A$11:$A$14,0)) -> 3 | F22: =INDEX($B$5:$E$5,MATCH($B22,$B$4:$E$4,0))/INDEX($D$11:$D$14,MATCH($B22,$A$11:$A$14,0)) -> 0.035 | G22: =INDEX($B$6:$E$6,MATCH($B22,$B$4:$E$4,0))/INDEX($D$11:$D$14,MATCH($B22,$A$11:$A$14,0)) -> 0.015 | H22: =INDEX($B$7:$E$7,MATCH($B22,$B$4:$E$4,0))/INDEX($D$11:$D$14,MATCH($B22,$A$11:$A$14,0)) -> 0.0025 | I22: =INDEX($B$8:$E$8,MATCH($B22,$B$4:$E$4,0))/INDEX($D$11:$D$14,MATCH($B22,$A$11:$A$14,0)) -> 0 | J22: =COUNTIF('요리 목록'!$D$5:$D$104,C22)+COUNTIF('요리 목록'!$F$5:$F$104,C22)+COUNTIF('요리 목록'!$H$5:$H$104,C22) -> 11
A23: 7 | B23: 일반 | C23: 마늘 | D23: =INDEX($B$11:$B$14,MATCH(B23,$A$11:$A$14,0)) -> 2 | E23: =INDEX($C$11:$C$14,MATCH(B23,$A$11:$A$14,0)) -> 3 | F23: =INDEX($B$5:$E$5,MATCH($B23,$B$4:$E$4,0))/INDEX($D$11:$D$14,MATCH($B23,$A$11:$A$14,0)) -> 0.035 | G23: =INDEX($B$6:$E$6,MATCH($B23,$B$4:$E$4,0))/INDEX($D$11:$D$14,MATCH($B23,$A$11:$A$14,0)) -> 0.015 | H23: =INDEX($B$7:$E$7,MATCH($B23,$B$4:$E$4,0))/INDEX($D$11:$D$14,MATCH($B23,$A$11:$A$14,0)) -> 0.0025 | I23: =INDEX($B$8:$E$8,MATCH($B23,$B$4:$E$4,0))/INDEX($D$11:$D$14,MATCH($B23,$A$11:$A$14,0)) -> 0 | J23: =COUNTIF('요리 목록'!$D$5:$D$104,C23)+COUNTIF('요리 목록'!$F$5:$F$104,C23)+COUNTIF('요리 목록'!$H$5:$H$104,C23) -> 10
A24: 8 | B24: 일반 | C24: 배추 | D24: =INDEX($B$11:$B$14,MATCH(B24,$A$11:$A$14,0)) -> 2 | E24: =INDEX($C$11:$C$14,MATCH(B24,$A$11:$A$14,0)) -> 3 | F24: =INDEX($B$5:$E$5,MATCH($B24,$B$4:$E$4,0))/INDEX($D$11:$D$14,MATCH($B24,$A$11:$A$14,0)) -> 0.035 | G24: =INDEX($B$6:$E$6,MATCH($B24,$B$4:$E$4,0))/INDEX($D$11:$D$14,MATCH($B24,$A$11:$A$14,0)) -> 0.015 | H24: =INDEX($B$7:$E$7,MATCH($B24,$B$4:$E$4,0))/INDEX($D$11:$D$14,MATCH($B24,$A$11:$A$14,0)) -> 0.0025 | I24: =INDEX($B$8:$E$8,MATCH($B24,$B$4:$E$4,0))/INDEX($D$11:$D$14,MATCH($B24,$A$11:$A$14,0)) -> 0 | J24: =COUNTIF('요리 목록'!$D$5:$D$104,C24)+COUNTIF('요리 목록'!$F$5:$F$104,C24)+COUNTIF('요리 목록'!$H$5:$H$104,C24) -> 4
A25: 9 | B25: 일반 | C25: 양배추 | D25: =INDEX($B$11:$B$14,MATCH(B25,$A$11:$A$14,0)) -> 2 | E25: =INDEX($C$11:$C$14,MATCH(B25,$A$11:$A$14,0)) -> 3 | F25: =INDEX($B$5:$E$5,MATCH($B25,$B$4:$E$4,0))/INDEX($D$11:$D$14,MATCH($B25,$A$11:$A$14,0)) -> 0.035 | G25: =INDEX($B$6:$E$6,MATCH($B25,$B$4:$E$4,0))/INDEX($D$11:$D$14,MATCH($B25,$A$11:$A$14,0)) -> 0.015 | H25: =INDEX($B$7:$E$7,MATCH($B25,$B$4:$E$4,0))/INDEX($D$11:$D$14,MATCH($B25,$A$11:$A$14,0)) -> 0.0025 | I25: =INDEX($B$8:$E$8,MATCH($B25,$B$4:$E$4,0))/INDEX($D$11:$D$14,MATCH($B25,$A$11:$A$14,0)) -> 0 | J25: =COUNTIF('요리 목록'!$D$5:$D$104,C25)+COUNTIF('요리 목록'!$F$5:$F$104,C25)+COUNTIF('요리 목록'!$H$5:$H$104,C25) -> 2
A26: 10 | B26: 일반 | C26: 상추 | D26: =INDEX($B$11:$B$14,MATCH(B26,$A$11:$A$14,0)) -> 2 | E26: =INDEX($C$11:$C$14,MATCH(B26,$A$11:$A$14,0)) -> 3 | F26: =INDEX($B$5:$E$5,MATCH($B26,$B$4:$E$4,0))/INDEX($D$11:$D$14,MATCH($B26,$A$11:$A$14,0)) -> 0.035 | G26: =INDEX($B$6:$E$6,MATCH($B26,$B$4:$E$4,0))/INDEX($D$11:$D$14,MATCH($B26,$A$11:$A$14,0)) -> 0.015 | H26: =INDEX($B$7:$E$7,MATCH($B26,$B$4:$E$4,0))/INDEX($D$11:$D$14,MATCH($B26,$A$11:$A$14,0)) -> 0.0025 | I26: =INDEX($B$8:$E$8,MATCH($B26,$B$4:$E$4,0))/INDEX($D$11:$D$14,MATCH($B26,$A$11:$A$14,0)) -> 0 | J26: =COUNTIF('요리 목록'!$D$5:$D$104,C26)+COUNTIF('요리 목록'!$F$5:$F$104,C26)+COUNTIF('요리 목록'!$H$5:$H$104,C26) -> 3
A27: 11 | B27: 일반 | C27: 시금치 | D27: =INDEX($B$11:$B$14,MATCH(B27,$A$11:$A$14,0)) -> 2 | E27: =INDEX($C$11:$C$14,MATCH(B27,$A$11:$A$14,0)) -> 3 | F27: =INDEX($B$5:$E$5,MATCH($B27,$B$4:$E$4,0))/INDEX($D$11:$D$14,MATCH($B27,$A$11:$A$14,0)) -> 0.035 | G27: =INDEX($B$6:$E$6,MATCH($B27,$B$4:$E$4,0))/INDEX($D$11:$D$14,MATCH($B27,$A$11:$A$14,0)) -> 0.015 | H27: =INDEX($B$7:$E$7,MATCH($B27,$B$4:$E$4,0))/INDEX($D$11:$D$14,MATCH($B27,$A$11:$A$14,0)) -> 0.0025 | I27: =INDEX($B$8:$E$8,MATCH($B27,$B$4:$E$4,0))/INDEX($D$11:$D$14,MATCH($B27,$A$11:$A$14,0)) -> 0 | J27: =COUNTIF('요리 목록'!$D$5:$D$104,C27)+COUNTIF('요리 목록'!$F$5:$F$104,C27)+COUNTIF('요리 목록'!$H$5:$H$104,C27) -> 3
A28: 12 | B28: 일반 | C28: 오이 | D28: =INDEX($B$11:$B$14,MATCH(B28,$A$11:$A$14,0)) -> 2 | E28: =INDEX($C$11:$C$14,MATCH(B28,$A$11:$A$14,0)) -> 3 | F28: =INDEX($B$5:$E$5,MATCH($B28,$B$4:$E$4,0))/INDEX($D$11:$D$14,MATCH($B28,$A$11:$A$14,0)) -> 0.035 | G28: =INDEX($B$6:$E$6,MATCH($B28,$B$4:$E$4,0))/INDEX($D$11:$D$14,MATCH($B28,$A$11:$A$14,0)) -> 0.015 | H28: =INDEX($B$7:$E$7,MATCH($B28,$B$4:$E$4,0))/INDEX($D$11:$D$14,MATCH($B28,$A$11:$A$14,0)) -> 0.0025 | I28: =INDEX($B$8:$E$8,MATCH($B28,$B$4:$E$4,0))/INDEX($D$11:$D$14,MATCH($B28,$A$11:$A$14,0)) -> 0 | J28: =COUNTIF('요리 목록'!$D$5:$D$104,C28)+COUNTIF('요리 목록'!$F$5:$F$104,C28)+COUNTIF('요리 목록'!$H$5:$H$104,C28) -> 6
... A71: 55 | B71: 전설 | C71: 불꽃 고추 | D71: =INDEX($B$11:$B$14,MATCH(B71,$A$11:$A$14,0)) -> 1 | E71: =INDEX($C$11:$C$14,MATCH(B71,$A$11:$A$14,0)) -> 1 | F71: =INDEX($B$5:$E$5,MATCH($B71,$B$4:$E$4,0))/INDEX($D$11:$D$14,MATCH($B71,$A$11:$A$14,0)) -> 0 | G71: =INDEX($B$6:$E$6,MATCH($B71,$B$4:$E$4,0))/INDEX($D$11:$D$14,MATCH($B71,$A$11:$A$14,0)) -> 0 | H71: =INDEX($B$7:$E$7,MATCH($B71,$B$4:$E$4,0))/INDEX($D$11:$D$14,MATCH($B71,$A$11:$A$14,0)) -> 0.01 | I71: =INDEX($B$8:$E$8,MATCH($B71,$B$4:$E$4,0))/INDEX($D$11:$D$14,MATCH($B71,$A$11:$A$14,0)) -> 0.1 | J71: =COUNTIF('요리 목록'!$D$5:$D$104,C71)+COUNTIF('요리 목록'!$F$5:$F$104,C71)+COUNTIF('요리 목록'!$H$5:$H$104,C71) -> 2
A73: 예: 일반 씨앗 → 감자 = 70% ÷ 20 = 3.5%. 쓰이는 요리 수가 0이면 그 작물로 만드는 요리가 없어요

Sheet 품질표
A1: 품질표
A2: 계획 §6. 작물 품질은 1~100. 평평한 끝까지 확률이 같고 그 위로 정규분포 꼬리처럼 줄어요. σ는 p(100)이 목표가 되게 맞춘 값
A4: 항목 | B4: 값 | H4: 품질 k | I4: 가중치 | J4: p(k) | K4: P(≤k) | L4: P(≥k)
A5: 평평한 끝 | B5: 30 | H5: 1 | I5: =IF(H5<=$B$5,1,EXP(-((H5-$B$5)^2)/(2*$B$6^2))) -> 1 | J5: =I5/SUM($I$5:$I$104) -> 0.015046964 | K5: =SUM($J$5:J5) -> 0.015046964 | L5: =1-K5+J5 -> 1
A6: σ (p(100)이 목표가 되게 맞춤) | B6: 30.06 | H6: 2 | I6: =IF(H6<=$B$5,1,EXP(-((H6-$B$5)^2)/(2*$B$6^2))) -> 1 | J6: =I6/SUM($I$5:$I$104) -> 0.015046964 | K6: =SUM($J$5:J6) -> 0.030093929 | L6: =1-K6+J6 -> 0.98495304
A7: p(100) 목표 | B7: 0.001 | H7: 3 | I7: =IF(H7<=$B$5,1,EXP(-((H7-$B$5)^2)/(2*$B$6^2))) -> 1 | J7: =I7/SUM($I$5:$I$104) -> 0.015046964 | K7: =SUM($J$5:J7) -> 0.045140893 | L7: =1-K7+J7 -> 0.96990607
A8: p(100) 지금 | B8: =J104 -> 0.00099981038 | H8: 4 | I8: =IF(H8<=$B$5,1,EXP(-((H8-$B$5)^2)/(2*$B$6^2))) -> 1 | J8: =I8/SUM($I$5:$I$104) -> 0.015046964 | K8: =SUM($J$5:J8) -> 0.060187858 | L8: =1-K8+J8 -> 0.95485911
A9: 차이 (0에 가까워야 함) | B9: =B8-B7 -> -1.8962209e-07 | H9: 5 | I9: =IF(H9<=$B$5,1,EXP(-((H9-$B$5)^2)/(2*$B$6^2))) -> 1 | J9: =I9/SUM($I$5:$I$104) -> 0.015046964 | K9: =SUM($J$5:J9) -> 0.075234822 | L9: =1-K9+J9 -> 0.93981214
A10: 평균 품질 | B10: =SUMPRODUCT(H5:H104,J5:J104) -> 36.181 | H10: 6 | I10: =IF(H10<=$B$5,1,EXP(-((H10-$B$5)^2)/(2*$B$6^2))) -> 1 | J10: =I10/SUM($I$5:$I$104) -> 0.015046964 | K10: =SUM($J$5:J10) -> 0.090281787 | L10: =1-K10+J10 -> 0.92476518
A11: P(≤30) | B11: =K34 -> 0.45140893 | H11: 7 | I11: =IF(H11<=$B$5,1,EXP(-((H11-$B$5)^2)/(2*$B$6^2))) -> 1 | J11: =I11/SUM($I$5:$I$104) -> 0.015046964 | K11: =SUM($J$5:J11) -> 0.10532875 | L11: =1-K11+J11 -> 0.90971821
A12: P(≥50) | B12: =L54 -> 0.28203025 | H12: 8 | I12: =IF(H12<=$B$5,1,EXP(-((H12-$B$5)^2)/(2*$B$6^2))) -> 1 | J12: =I12/SUM($I$5:$I$104) -> 0.015046964 | K12: =SUM($J$5:J12) -> 0.12037572 | L12: =1-K12+J12 -> 0.89467125
A13: P(≥70) | B13: =L74 -> 0.096261697 | H13: 9 | I13: =IF(H13<=$B$5,1,EXP(-((H13-$B$5)^2)/(2*$B$6^2))) -> 1 | J13: =I13/SUM($I$5:$I$104) -> 0.015046964 | K13: =SUM($J$5:J13) -> 0.13542268 | L13: =1-K13+J13 -> 0.87962428
A14: P(≥90) | B14: =L94 -> 0.016302471 | H14: 10 | I14: =IF(H14<=$B$5,1,EXP(-((H14-$B$5)^2)/(2*$B$6^2))) -> 1 | J14: =I14/SUM($I$5:$I$104) -> 0.015046964 | K14: =SUM($J$5:J14) -> 0.15046964 | L14: =1-K14+J14 -> 0.86457732
H15: 11 | I15: =IF(H15<=$B$5,1,EXP(-((H15-$B$5)^2)/(2*$B$6^2))) -> 1 | J15: =I15/SUM($I$5:$I$104) -> 0.015046964 | K15: =SUM($J$5:J15) -> 0.16551661 | L15: =1-K15+J15 -> 0.84953036
A16: 정성스레 (제작) | B16: 기준 | C16: 그냥 | D16: 다시 굴린 뒤 | H16: 12 | I16: =IF(H16<=$B$5,1,EXP(-((H16-$B$5)^2)/(2*$B$6^2))) -> 1 | J16: =I16/SUM($I$5:$I$104) -> 0.015046964 | K16: =SUM($J$5:J16) -> 0.18056357 | L16: =1-K16+J16 -> 0.83448339
A17: 정성스레 1 (이하면 한 번 다시) | B17: 8 | C17: =INDEX($K$5:$K$104,B17) -> 0.12037572 | D17: =C17^2 -> 0.014490313 | H17: 13 | I17: =IF(H17<=$B$5,1,EXP(-((H17-$B$5)^2)/(2*$B$6^2))) -> 1 | J17: =I17/SUM($I$5:$I$104) -> 0.015046964 | K17: =SUM($J$5:J17) -> 0.19561054 | L17: =1-K17+J17 -> 0.81943643
A18: 정성스레 2 (이하면 한 번 다시) | B18: 16 | C18: =INDEX($K$5:$K$104,B18) -> 0.24075143 | D18: =C18^2 -> 0.057961252 | H18: 14 | I18: =IF(H18<=$B$5,1,EXP(-((H18-$B$5)^2)/(2*$B$6^2))) -> 1 | J18: =I18/SUM($I$5:$I$104) -> 0.015046964 | K18: =SUM($J$5:J18) -> 0.2106575 | L18: =1-K18+J18 -> 0.80438946
H19: 15 | I19: =IF(H19<=$B$5,1,EXP(-((H19-$B$5)^2)/(2*$B$6^2))) -> 1 | J19: =I19/SUM($I$5:$I$104) -> 0.015046964 | K19: =SUM($J$5:J19) -> 0.22570447 | L19: =1-K19+J19 -> 0.7893425
A20: 10칸 묶음 | B20: 부터 | C20: 까지 | D20: 확률 | H20: 16 | I20: =IF(H20<=$B$5,1,EXP(-((H20-$B$5)^2)/(2*$B$6^2))) -> 1 | J20: =I20/SUM($I$5:$I$104) -> 0.015046964 | K20: =SUM($J$5:J20) -> 0.24075143 | L20: =1-K20+J20 -> 0.77429553
A21: 1–10 | B21: 1 | C21: 10 | D21: =SUMIFS($J$5:$J$104,$H$5:$H$104,">="&B21,$H$5:$H$104,"<="&C21) -> 0.15046964 | H21: 17 | I21: =IF(H21<=$B$5,1,EXP(-((H21-$B$5)^2)/(2*$B$6^2))) -> 1 | J21: =I21/SUM($I$5:$I$104) -> 0.015046964 | K21: =SUM($J$5:J21) -> 0.2557984 | L21: =1-K21+J21 -> 0.75924857
A22: 11–20 | B22: 11 | C22: 20 | D22: =SUMIFS($J$5:$J$104,$H$5:$H$104,">="&B22,$H$5:$H$104,"<="&C22) -> 0.15046964 | H22: 18 | I22: =IF(H22<=$B$5,1,EXP(-((H22-$B$5)^2)/(2*$B$6^2))) -> 1 | J22: =I22/SUM($I$5:$I$104) -> 0.015046964 | K22: =SUM($J$5:J22) -> 0.27084536 | L22: =1-K22+J22 -> 0.7442016
A23: 21–30 | B23: 21 | C23: 30 | D23: =SUMIFS($J$5:$J$104,$H$5:$H$104,">="&B23,$H$5:$H$104,"<="&C23) -> 0.15046964 | H23: 19 | I23: =IF(H23<=$B$5,1,EXP(-((H23-$B$5)^2)/(2*$B$6^2))) -> 1 | J23: =I23/SUM($I$5:$I$104) -> 0.015046964 | K23: =SUM($J$5:J23) -> 0.28589232 | L23: =1-K23+J23 -> 0.72915464
A24: 31–40 | B24: 31 | C24: 40 | D24: =SUMIFS($J$5:$J$104,$H$5:$H$104,">="&B24,$H$5:$H$104,"<="&C24) -> 0.14732163 | H24: 20 | I24: =IF(H24<=$B$5,1,EXP(-((H24-$B$5)^2)/(2*$B$6^2))) -> 1 | J24: =I24/SUM($I$5:$I$104) -> 0.015046964 | K24: =SUM($J$5:J24) -> 0.30093929 | L24: =1-K24+J24 -> 0.71410768
A25: 41–50 | B25: 41 | C25: 50 | D25: =SUMIFS($J$5:$J$104,$H$5:$H$104,">="&B25,$H$5:$H$104,"<="&C25) -> 0.13129853 | H25: 21 | I25: =IF(H25<=$B$5,1,EXP(-((H25-$B$5)^2)/(2*$B$6^2))) -> 1 | J25: =I25/SUM($I$5:$I$104) -> 0.015046964 | K25: =SUM($J$5:J25) -> 0.31598625 | L25: =1-K25+J25 -> 0.69906071
A26: 51–60 | B26: 51 | C26: 60 | D26: =SUMIFS($J$5:$J$104,$H$5:$H$104,">="&B26,$H$5:$H$104,"<="&C26) -> 0.10486422 | H26: 22 | I26: =IF(H26<=$B$5,1,EXP(-((H26-$B$5)^2)/(2*$B$6^2))) -> 1 | J26: =I26/SUM($I$5:$I$104) -> 0.015046964 | K26: =SUM($J$5:J26) -> 0.33103322 | L26: =1-K26+J26 -> 0.68401375
A27: 61–70 | B27: 61 | C27: 70 | D27: =SUMIFS($J$5:$J$104,$H$5:$H$104,">="&B27,$H$5:$H$104,"<="&C27) -> 0.075052948 | H27: 23 | I27: =IF(H27<=$B$5,1,EXP(-((H27-$B$5)^2)/(2*$B$6^2))) -> 1 | J27: =I27/SUM($I$5:$I$104) -> 0.015046964 | K27: =SUM($J$5:J27) -> 0.34608018 | L27: =1-K27+J27 -> 0.66896678
A28: 71–80 | B28: 71 | C28: 80 | D28: =SUMIFS($J$5:$J$104,$H$5:$H$104,">="&B28,$H$5:$H$104,"<="&C28) -> 0.048137057 | H28: 24 | I28: =IF(H28<=$B$5,1,EXP(-((H28-$B$5)^2)/(2*$B$6^2))) -> 1 | J28: =I28/SUM($I$5:$I$104) -> 0.015046964 | K28: =SUM($J$5:J28) -> 0.36112715 | L28: =1-K28+J28 -> 0.65391982
A29: 81–90 | B29: 81 | C29: 90 | D29: =SUMIFS($J$5:$J$104,$H$5:$H$104,">="&B29,$H$5:$H$104,"<="&C29) -> 0.027666902 | H29: 25 | I29: =IF(H29<=$B$5,1,EXP(-((H29-$B$5)^2)/(2*$B$6^2))) -> 1 | J29: =I29/SUM($I$5:$I$104) -> 0.015046964 | K29: =SUM($J$5:J29) -> 0.37617411 | L29: =1-K29+J29 -> 0.63887285
A30: 91–100 | B30: 91 | C30: 100 | D30: =SUMIFS($J$5:$J$104,$H$5:$H$104,">="&B30,$H$5:$H$104,"<="&C30) -> 0.014249778 | H30: 26 | I30: =IF(H30<=$B$5,1,EXP(-((H30-$B$5)^2)/(2*$B$6^2))) -> 1 | J30: =I30/SUM($I$5:$I$104) -> 0.015046964 | K30: =SUM($J$5:J30) -> 0.39122108 | L30: =1-K30+J30 -> 0.62382589
A31: 합계 | D31: =SUM(D21:D30) -> 1 | H31: 27 | I31: =IF(H31<=$B$5,1,EXP(-((H31-$B$5)^2)/(2*$B$6^2))) -> 1 | J31: =I31/SUM($I$5:$I$104) -> 0.015046964 | K31: =SUM($J$5:J31) -> 0.40626804 | L31: =1-K31+J31 -> 0.60877892
H32: 28 | I32: =IF(H32<=$B$5,1,EXP(-((H32-$B$5)^2)/(2*$B$6^2))) -> 1 | J32: =I32/SUM($I$5:$I$104) -> 0.015046964 | K32: =SUM($J$5:J32) -> 0.421315 | L32: =1-K32+J32 -> 0.59373196
H33: 29 | I33: =IF(H33<=$B$5,1,EXP(-((H33-$B$5)^2)/(2*$B$6^2))) -> 1 | J33: =I33/SUM($I$5:$I$104) -> 0.015046964 | K33: =SUM($J$5:J33) -> 0.43636197 | L33: =1-K33+J33 -> 0.578685
H34: 30 | I34: =IF(H34<=$B$5,1,EXP(-((H34-$B$5)^2)/(2*$B$6^2))) -> 1 | J34: =I34/SUM($I$5:$I$104) -> 0.015046964 | K34: =SUM($J$5:J34) -> 0.45140893 | L34: =1-K34+J34 -> 0.56363803
H35: 31 | I35: =IF(H35<=$B$5,1,EXP(-((H35-$B$5)^2)/(2*$B$6^2))) -> 0.99944681 | J35: =I35/SUM($I$5:$I$104) -> 0.015038641 | K35: =SUM($J$5:J35) -> 0.46644757 | L35: =1-K35+J35 -> 0.54859107
H36: 32 | I36: =IF(H36<=$B$5,1,EXP(-((H36-$B$5)^2)/(2*$B$6^2))) -> 0.99778909 | J36: =I36/SUM($I$5:$I$104) -> 0.015013697 | K36: =SUM($J$5:J36) -> 0.48146127 | L36: =1-K36+J36 -> 0.53355243
H37: 33 | I37: =IF(H37<=$B$5,1,EXP(-((H37-$B$5)^2)/(2*$B$6^2))) -> 0.99503232 | J37: =I37/SUM($I$5:$I$104) -> 0.014972216 | K37: =SUM($J$5:J37) -> 0.49643349 | L37: =1-K37+J37 -> 0.51853873
H38: 34 | I38: =IF(H38<=$B$5,1,EXP(-((H38-$B$5)^2)/(2*$B$6^2))) -> 0.99118564 | J38: =I38/SUM($I$5:$I$104) -> 0.014914335 | K38: =SUM($J$5:J38) -> 0.51134782 | L38: =1-K38+J38 -> 0.50356651
H39: 35 | I39: =IF(H39<=$B$5,1,EXP(-((H39-$B$5)^2)/(2*$B$6^2))) -> 0.98626174 | J39: =I39/SUM($I$5:$I$104) -> 0.014840245 | K39: =SUM($J$5:J39) -> 0.52618807 | L39: =1-K39+J39 -> 0.48865218
H40: 36 | I40: =IF(H40<=$B$5,1,EXP(-((H40-$B$5)^2)/(2*$B$6^2))) -> 0.98027686 | J40: =I40/SUM($I$5:$I$104) -> 0.014750191 | K40: =SUM($J$5:J40) -> 0.54093826 | L40: =1-K40+J40 -> 0.47381193
H41: 37 | I41: =IF(H41<=$B$5,1,EXP(-((H41-$B$5)^2)/(2*$B$6^2))) -> 0.97325062 | J41: =I41/SUM($I$5:$I$104) -> 0.014644467 | K41: =SUM($J$5:J41) -> 0.55558273 | L41: =1-K41+J41 -> 0.45906174
...

Sheet 제작
A1: 제작 (강화 39단계)
A2: 계획 §7 · §8. 같은 줄은 번호 순서대로만. 비용은 자재 · 고급 자재 · 돈. 목표일 = 기준 플레이어가 그 단계를 만드는 날 (14일째에 다 만듦)
A4: 돈 계산 | B4: 값
A5: 고급 자재 가중치 (돈 = (자재 + 고급 자재 × 이 값) × 배수) | B5: 5
A7: 목표일부터 | B7: 배수
A8: 1 | B8: 0
A9: 2 | B9: 10
A10: 4 | B10: 20
A11: 1일 단계 돈 없음 (첫날은 아직 요리를 못 함) · 2~3일 반값 (요리 재료가 덜 모임)
A13: 줄 | B13: 단계 | C13: 효과 | D13: 자재 | E13: 고급 자재 | F13: 목표일 | G13: 돈 | I13: 줄 | J13: 단계 수 | K13: 자재 합 | L13: 고급 자재 합 | M13: 돈 합
A14: 밭 | B14: 1 | C14: 밭 +1칸 (2 → 3칸) | D14: 8 | E14: 0 | F14: 1 | G14: =(D14+E14*$B$5)*INDEX($B$8:$B$10,MATCH(F14,$A$8:$A$10,1)) -> 0 | I14: 밭 | J14: =COUNTIF($A$14:$A$52,I14) -> 6 | K14: =SUMIF($A$14:$A$52,I14,$D$14:$D$52) -> 220 | L14: =SUMIF($A$14:$A$52,I14,$E$14:$E$52) -> 25 | M14: =SUMIF($A$14:$A$52,I14,$G$14:$G$52) -> 6190
A15: 밭 | B15: 2 | C15: 밭 +1칸 (3 → 4칸) | D15: 15 | E15: 0 | F15: 1 | G15: =(D15+E15*$B$5)*INDEX($B$8:$B$10,MATCH(F15,$A$8:$A$10,1)) -> 0 | I15: 씨앗 합성기 | J15: =COUNTIF($A$14:$A$52,I15) -> 1 | K15: =SUMIF($A$14:$A$52,I15,$D$14:$D$52) -> 30 | L15: =SUMIF($A$14:$A$52,I15,$E$14:$E$52) -> 5 | M15: =SUMIF($A$14:$A$52,I15,$G$14:$G$52) -> 550
A16: 밭 | B16: 3 | C16: 밭 +1칸 (4 → 5칸) | D16: 25 | E16: 0 | F16: 2 | G16: =(D16+E16*$B$5)*INDEX($B$8:$B$10,MATCH(F16,$A$8:$A$10,1)) -> 250 | I16: 효율 증대 | J16: =COUNTIF($A$14:$A$52,I16) -> 3 | K16: =SUMIF($A$14:$A$52,I16,$D$14:$D$52) -> 140 | L16: =SUMIF($A$14:$A$52,I16,$E$14:$E$52) -> 38 | M16: =SUMIF($A$14:$A$52,I16,$G$14:$G$52) -> 6600
A17: 밭 | B17: 4 | C17: 밭 +1칸 (5 → 6칸) | D17: 40 | E17: 4 | F17: 4 | G17: =(D17+E17*$B$5)*INDEX($B$8:$B$10,MATCH(F17,$A$8:$A$10,1)) -> 1200 | I17: 정성스레 | J17: =COUNTIF($A$14:$A$52,I17) -> 2 | K17: =SUMIF($A$14:$A$52,I17,$D$14:$D$52) -> 90 | L17: =SUMIF($A$14:$A$52,I17,$E$14:$E$52) -> 25 | M17: =SUMIF($A$14:$A$52,I17,$G$14:$G$52) -> 3600
A18: 밭 | B18: 5 | C18: 밭 +1칸 (6 → 7칸) | D18: 57 | E18: 8 | F18: 6 | G18: =(D18+E18*$B$5)*INDEX($B$8:$B$10,MATCH(F18,$A$8:$A$10,1)) -> 1940 | I18: 시설 강화 | J18: =COUNTIF($A$14:$A$52,I18) -> 3 | K18: =SUMIF($A$14:$A$52,I18,$D$14:$D$52) -> 130 | L18: =SUMIF($A$14:$A$52,I18,$E$14:$E$52) -> 26 | M18: =SUMIF($A$14:$A$52,I18,$G$14:$G$52) -> 4200
A19: 밭 | B19: 6 | C19: 밭 +1칸 (7 → 8칸) | D19: 75 | E19: 13 | F19: 10 | G19: =(D19+E19*$B$5)*INDEX($B$8:$B$10,MATCH(F19,$A$8:$A$10,1)) -> 2800 | I19: 재사용 | J19: =COUNTIF($A$14:$A$52,I19) -> 4 | K19: =SUMIF($A$14:$A$52,I19,$D$14:$D$52) -> 110 | L19: =SUMIF($A$14:$A$52,I19,$E$14:$E$52) -> 20 | M19: =SUMIF($A$14:$A$52,I19,$G$14:$G$52) -> 4040
A20: 씨앗 합성기 | B20: – | C20: 아래 등급 씨앗 10개 → 윗등급 1개 (항상 성공) | D20: 30 | E20: 5 | F20: 2 | G20: =(D20+E20*$B$5)*INDEX($B$8:$B$10,MATCH(F20,$A$8:$A$10,1)) -> 550 | I20: 풍작 | J20: =COUNTIF($A$14:$A$52,I20) -> 16 | K20: =SUMIF($A$14:$A$52,I20,$D$14:$D$52) -> 380 | L20: =SUMIF($A$14:$A$52,I20,$E$14:$E$52) -> 76 | M20: =SUMIF($A$14:$A$52,I20,$G$14:$G$52) -> 13810
A21: 효율 증대 | B21: 1 | C21: 합성 배율 9:1 | D21: 35 | E21: 8 | F21: 5 | G21: =(D21+E21*$B$5)*INDEX($B$8:$B$10,MATCH(F21,$A$8:$A$10,1)) -> 1500 | I21: 탐험 강화 | J21: =COUNTIF($A$14:$A$52,I21) -> 2 | K21: =SUMIF($A$14:$A$52,I21,$D$14:$D$52) -> 125 | L21: =SUMIF($A$14:$A$52,I21,$E$14:$E$52) -> 25 | M21: =SUMIF($A$14:$A$52,I21,$G$14:$G$52) -> 5000
A22: 효율 증대 | B22: 2 | C22: 합성 배율 8:1 | D22: 45 | E22: 12 | F22: 7 | G22: =(D22+E22*$B$5)*INDEX($B$8:$B$10,MATCH(F22,$A$8:$A$10,1)) -> 2100 | I22: 장신구 착용 | J22: =COUNTIF($A$14:$A$52,I22) -> 2 | K22: =SUMIF($A$14:$A$52,I22,$D$14:$D$52) -> 190 | L22: =SUMIF($A$14:$A$52,I22,$E$14:$E$52) -> 37 | M22: =SUMIF($A$14:$A$52,I22,$G$14:$G$52) -> 7500
A23: 효율 증대 | B23: 3 | C23: 합성 배율 7:1 | D23: 60 | E23: 18 | F23: 12 | G23: =(D23+E23*$B$5)*INDEX($B$8:$B$10,MATCH(F23,$A$8:$A$10,1)) -> 3000 | I23: 합계 | J23: =SUM(J14:J22) -> 39 | K23: =SUM(K14:K22) -> 1415 | L23: =SUM(L14:L22) -> 277 | M23: =SUM(M14:M22) -> 51490
A24: 정성스레 | B24: 1 | C24: 품질 8 이하면 한 번 다시 굴림 | D24: 30 | E24: 8 | F24: 3 | G24: =(D24+E24*$B$5)*INDEX($B$8:$B$10,MATCH(F24,$A$8:$A$10,1)) -> 700
A25: 정성스레 | B25: 2 | C25: 품질 16 이하면 한 번 다시 굴림 | D25: 60 | E25: 17 | F25: 9 | G25: =(D25+E25*$B$5)*INDEX($B$8:$B$10,MATCH(F25,$A$8:$A$10,1)) -> 2900
A26: 시설 강화 | B26: 1 | C26: 고급 씨앗 심기 가능 | D26: 10 | E26: 0 | F26: 1 | G26: =(D26+E26*$B$5)*INDEX($B$8:$B$10,MATCH(F26,$A$8:$A$10,1)) -> 0
A27: 시설 강화 | B27: 2 | C27: 희귀 씨앗 심기 가능 | D27: 40 | E27: 8 | F27: 3 | G27: =(D27+E27*$B$5)*INDEX($B$8:$B$10,MATCH(F27,$A$8:$A$10,1)) -> 800
A28: 시설 강화 | B28: 3 | C28: 전설 씨앗 심기 가능 | D28: 80 | E28: 18 | F28: 8 | G28: =(D28+E28*$B$5)*INDEX($B$8:$B$10,MATCH(F28,$A$8:$A$10,1)) -> 3400
A29: 재사용 | B29: 1 | C29: 일반 · 고급 작물 수확 때 씨앗 1개 반환 10% | D29: 8 | E29: 0 | F29: 1 | G29: =(D29+E29*$B$5)*INDEX($B$8:$B$10,MATCH(F29,$A$8:$A$10,1)) -> 0
A30: 재사용 | B30: 2 | C30: 반환 확률 20% | D30: 20 | E30: 3 | F30: 4 | G30: =(D30+E30*$B$5)*INDEX($B$8:$B$10,MATCH(F30,$A$8:$A$10,1)) -> 700
A31: 재사용 | B31: 3 | C31: 반환 확률 30% | D31: 32 | E31: 6 | F31: 6 | G31: =(D31+E31*$B$5)*INDEX($B$8:$B$10,MATCH(F31,$A$8:$A$10,1)) -> 1240
A32: 재사용 | B32: 4 | C32: 희귀 작물 수확 때 씨앗 1개 반환 10% | D32: 50 | E32: 11 | F32: 11 | G32: =(D32+E32*$B$5)*INDEX($B$8:$B$10,MATCH(F32,$A$8:$A$10,1)) -> 2100
A33: 풍작 | B33: 1 | C33: 일반 작물 수확 때 50% 확률로 +1 | D33: 5 | E33: 0 | F33: 1 | G33: =(D33+E33*$B$5)*INDEX($B$8:$B$10,MATCH(F33,$A$8:$A$10,1)) -> 0
A34: 풍작 | B34: 2 | C34: 고급 작물 수확 때 50% 확률로 +1 | D34: 7 | E34: 0 | F34: 1 | G34: =(D34+E34*$B$5)*INDEX($B$8:$B$10,MATCH(F34,$A$8:$A$10,1)) -> 0
A35: 풍작 | B35: 3 | C35: 풍작 1의 확률 → 100% | D35: 8 | E35: 0 | F35: 1 | G35: =(D35+E35*$B$5)*INDEX($B$8:$B$10,MATCH(F35,$A$8:$A$10,1)) -> 0
... A52: 장신구 착용 | B52: 2 | C52: 착용 장신구 +1개 (2 → 3개) | D52: 170 | E52: 33 | F52: 13 | G52: =(D52+E52*$B$5)*INDEX($B$8:$B$10,MATCH(F52,$A$8:$A$10,1)) -> 6700
A53: 합계 | B53: =COUNTA(A14:A52)&"단계" -> 39단계 | D53: =SUM(D14:D52) -> 1415 | E53: =SUM(E14:E52) -> 277 | G53: =SUM(G14:G52) -> 51490
A55: 날짜별 검산: 목표일 순서대로 사면 누적 비용 ≤ 누적 수입인지 (탐험은 48시간 안에 한 번씩 받는 기준, 돈은 Claude 어림)
A56: 날 | B56: 탐험 강화 단계 | C56: 하루 굴림 | D56: 자재 수입 | E56: 고급 자재 수입 (상자 포함) | F56: 누적 자재 수입 | G56: 누적 자재 비용 | H56: 자재 | I56: 누적 고급 자재 수입 | J56: 누적 고급 자재 비용 | K56: 고급 자재 | L56: 하루 돈 수입 (어림) | M56: 실제로 들어오는 비율 | N56: 누적 돈 수입 (들어온 것) | O56: 누적 돈 비용 | P56: 돈 비용 ÷ 수입
A57: 1 | B57: =COUNTIFS($A$14:$A$52,"탐험 강화",$F$14:$F$52,"<"&A57) -> 0 | C57: =24*(탐험!$B$5+B57) -> 72 | D57: =C57*탐험!$H$21 -> 79.8336 | E57: =C57*(탐험!$H$22+탐험!$C$27*탐험!$E$39) -> 16.110735 | F57: =SUM($D$57:D57) -> 79.8336 | G57: =SUMIF($F$14:$F$52,"<="&A57,$D$14:$D$52) -> 71 | H57: =IF(G57<=F57,"OK","모자람") -> OK | I57: =SUM($E$57:E57) -> 16.110735 | J57: =SUMIF($F$14:$F$52,"<="&A57,$E$14:$E$52) -> 0 | K57: =IF(J57<=I57,"OK","모자람") -> OK | L57: 1880 | M57: 0.3 | N57: =SUM($L$57:L57)*M57 -> 564 | O57: =SUMIF($F$14:$F$52,"<="&A57,$G$14:$G$52) -> 0 | P57: =IF(N57=0,0,O57/N57) -> 0
A58: 2 | B58: =COUNTIFS($A$14:$A$52,"탐험 강화",$F$14:$F$52,"<"&A58) -> 0 | C58: =24*(탐험!$B$5+B58) -> 72 | D58: =C58*탐험!$H$21 -> 79.8336 | E58: =C58*(탐험!$H$22+탐험!$C$27*탐험!$E$39) -> 16.110735 | F58: =SUM($D$57:D58) -> 159.6672 | G58: =SUMIF($F$14:$F$52,"<="&A58,$D$14:$D$52) -> 150 | H58: =IF(G58<=F58,"OK","모자람") -> OK | I58: =SUM($E$57:E58) -> 32.221469 | J58: =SUMIF($F$14:$F$52,"<="&A58,$E$14:$E$52) -> 10 | K58: =IF(J58<=I58,"OK","모자람") -> OK | L58: 2700 | M58: 0.5 | N58: =SUM($L$57:L58)*M58 -> 2290 | O58: =SUMIF($F$14:$F$52,"<="&A58,$G$14:$G$52) -> 1290 | P58: =IF(N58=0,0,O58/N58) -> 0.56331878
A59: 3 | B59: =COUNTIFS($A$14:$A$52,"탐험 강화",$F$14:$F$52,"<"&A59) -> 0 | C59: =24*(탐험!$B$5+B59) -> 72 | D59: =C59*탐험!$H$21 -> 79.8336 | E59: =C59*(탐험!$H$22+탐험!$C$27*탐험!$E$39) -> 16.110735 | F59: =SUM($D$57:D59) -> 239.5008 | G59: =SUMIF($F$14:$F$52,"<="&A59,$D$14:$D$52) -> 235 | H59: =IF(G59<=F59,"OK","모자람") -> OK | I59: =SUM($E$57:E59) -> 48.332204 | J59: =SUMIF($F$14:$F$52,"<="&A59,$E$14:$E$52) -> 29 | K59: =IF(J59<=I59,"OK","모자람") -> OK | L59: 5810 | M59: 0.65 | N59: =SUM($L$57:L59)*M59 -> 6753.5 | O59: =SUMIF($F$14:$F$52,"<="&A59,$G$14:$G$52) -> 3090 | P59: =IF(N59=0,0,O59/N59) -> 0.45754053
A60: 4 | B60: =COUNTIFS($A$14:$A$52,"탐험 강화",$F$14:$F$52,"<"&A60) -> 0 | C60: =24*(탐험!$B$5+B60) -> 72 | D60: =C60*탐험!$H$21 -> 79.8336 | E60: =C60*(탐험!$H$22+탐험!$C$27*탐험!$E$39) -> 16.110735 | F60: =SUM($D$57:D60) -> 319.3344 | G60: =SUMIF($F$14:$F$52,"<="&A60,$D$14:$D$52) -> 313 | H60: =IF(G60<=F60,"OK","모자람") -> OK | I60: =SUM($E$57:E60) -> 64.442939 | J60: =SUMIF($F$14:$F$52,"<="&A60,$E$14:$E$52) -> 40 | K60: =IF(J60<=I60,"OK","모자람") -> OK | L60: 6820 | M60: 0.75 | N60: =SUM($L$57:L60)*M60 -> 12907.5 | O60: =SUMIF($F$14:$F$52,"<="&A60,$G$14:$G$52) -> 5750 | P60: =IF(N60=0,0,O60/N60) -> 0.44547744
...

Sheet 요리·별
A1: 요리 · 별 · 판매
A2: 계획 §14. 요리 = 레시피 고르기 → 재료 작물 고르기 → 요리. 별은 룰렛을 실패할 때까지 돌린 성공 횟수 (최대 3성)
A4: 요리 등급 | B4: 기본 가격 (돈) | C4: 별 감점 | D4: 도감 개수 | E4: 요리 수
A5: 일반 | B5: 10 | C5: 0 | D5: 1 | E5: =COUNTIF('요리 목록'!$B$5:$B$104,A5) -> 40
A6: 고급 | B6: 30 | C6: 5 | D6: 2 | E6: =COUNTIF('요리 목록'!$B$5:$B$104,A6) -> 30
A7: 희귀 | B7: 150 | C7: 10 | D7: 2 | E7: =COUNTIF('요리 목록'!$B$5:$B$104,A7) -> 20
A8: 전설 | B8: 1000 | C8: 15 | D8: 1 | E8: =COUNTIF('요리 목록'!$B$5:$B$104,A8) -> 10
A9: 합계 | D9: =SUM(D5:D8) -> 6 | E9: =SUM(E5:E8) -> 100
A11: 원래 값 랜덤 폭 (±) | B11: 0.1
A12: 원래 값 = 기본 가격 × (1 ± 폭) 안에서 요리마다 한 번 정해 고정 (시드 farm:price:{요리 id}, 정수로 반올림)
A14: 별 | B14: 판매 배율
A15: 0성 | B15: 1
A16: 1성 | B16: 5
A17: 2성 | B17: 30
A18: 3성 | B18: 200
A20: 룰렛 | B20: 값
A21: 한 번 성공할 때마다 빼는 값 | B21: 25
A22: 성공 확률 하한 | B22: 0.05
A23: 성공 확률 상한 | B23: 0.95
A24: k번째 룰렛 성공 확률 = 평균 품질 − 등급 감점 − 25 × (k − 1) (하한 ~ 상한으로 자름). 평균 품질 = 재료 작물 품질 합 ÷ 재료 개수
A26: 요리 등급 | B26: 재료 평균 품질 | C26: 1번째 성공 | D26: 2번째 성공 | E26: 3번째 성공 | F26: 0성 | G26: 1성 | H26: 2성 | I26: 3성 | J26: 기대 배율 | K26: 기대 판매 값 (기본 가격)
A27: 일반 | B27: 36 | C27: =MIN($B$23,MAX($B$22,($B27-INDEX($C$5:$C$8,MATCH($A27,$A$5:$A$8,0))-$B$21*0)/100)) -> 0.36 | D27: =MIN($B$23,MAX($B$22,($B27-INDEX($C$5:$C$8,MATCH($A27,$A$5:$A$8,0))-$B$21*1)/100)) -> 0.11 | E27: =MIN($B$23,MAX($B$22,($B27-INDEX($C$5:$C$8,MATCH($A27,$A$5:$A$8,0))-$B$21*2)/100)) -> 0.05 | F27: =1-C27 -> 0.64 | G27: =C27*(1-D27) -> 0.3204 | H27: =C27*D27*(1-E27) -> 0.03762 | I27: =C27*D27*E27 -> 0.00198 | J27: =F27*$B$15+G27*$B$16+H27*$B$17+I27*$B$18 -> 3.7666 | K27: =J27*INDEX($B$5:$B$8,MATCH($A27,$A$5:$A$8,0)) -> 37.666
A28: 일반 | B28: 62 | C28: =MIN($B$23,MAX($B$22,($B28-INDEX($C$5:$C$8,MATCH($A28,$A$5:$A$8,0))-$B$21*0)/100)) -> 0.62 | D28: =MIN($B$23,MAX($B$22,($B28-INDEX($C$5:$C$8,MATCH($A28,$A$5:$A$8,0))-$B$21*1)/100)) -> 0.37 | E28: =MIN($B$23,MAX($B$22,($B28-INDEX($C$5:$C$8,MATCH($A28,$A$5:$A$8,0))-$B$21*2)/100)) -> 0.12 | F28: =1-C28 -> 0.38 | G28: =C28*(1-D28) -> 0.3906 | H28: =C28*D28*(1-E28) -> 0.201872 | I28: =C28*D28*E28 -> 0.027528 | J28: =F28*$B$15+G28*$B$16+H28*$B$17+I28*$B$18 -> 13.89476 | K28: =J28*INDEX($B$5:$B$8,MATCH($A28,$A$5:$A$8,0)) -> 138.9476
A29: 일반 | B29: 78 | C29: =MIN($B$23,MAX($B$22,($B29-INDEX($C$5:$C$8,MATCH($A29,$A$5:$A$8,0))-$B$21*0)/100)) -> 0.78 | D29: =MIN($B$23,MAX($B$22,($B29-INDEX($C$5:$C$8,MATCH($A29,$A$5:$A$8,0))-$B$21*1)/100)) -> 0.53 | E29: =MIN($B$23,MAX($B$22,($B29-INDEX($C$5:$C$8,MATCH($A29,$A$5:$A$8,0))-$B$21*2)/100)) -> 0.28 | F29: =1-C29 -> 0.22 | G29: =C29*(1-D29) -> 0.3666 | H29: =C29*D29*(1-E29) -> 0.297648 | I29: =C29*D29*E29 -> 0.115752 | J29: =F29*$B$15+G29*$B$16+H29*$B$17+I29*$B$18 -> 34.13284 | K29: =J29*INDEX($B$5:$B$8,MATCH($A29,$A$5:$A$8,0)) -> 341.3284
A30: 일반 | B30: 90 | C30: =MIN($B$23,MAX($B$22,($B30-INDEX($C$5:$C$8,MATCH($A30,$A$5:$A$8,0))-$B$21*0)/100)) -> 0.9 | D30: =MIN($B$23,MAX($B$22,($B30-INDEX($C$5:$C$8,MATCH($A30,$A$5:$A$8,0))-$B$21*1)/100)) -> 0.65 | E30: =MIN($B$23,MAX($B$22,($B30-INDEX($C$5:$C$8,MATCH($A30,$A$5:$A$8,0))-$B$21*2)/100)) -> 0.4 | F30: =1-C30 -> 0.1 | G30: =C30*(1-D30) -> 0.315 | H30: =C30*D30*(1-E30) -> 0.351 | I30: =C30*D30*E30 -> 0.234 | J30: =F30*$B$15+G30*$B$16+H30*$B$17+I30*$B$18 -> 59.005 | K30: =J30*INDEX($B$5:$B$8,MATCH($A30,$A$5:$A$8,0)) -> 590.05
A31: 고급 | B31: 36 | C31: =MIN($B$23,MAX($B$22,($B31-INDEX($C$5:$C$8,MATCH($A31,$A$5:$A$8,0))-$B$21*0)/100)) -> 0.31 | D31: =MIN($B$23,MAX($B$22,($B31-INDEX($C$5:$C$8,MATCH($A31,$A$5:$A$8,0))-$B$21*1)/100)) -> 0.06 | E31: =MIN($B$23,MAX($B$22,($B31-INDEX($C$5:$C$8,MATCH($A31,$A$5:$A$8,0))-$B$21*2)/100)) -> 0.05 | F31: =1-C31 -> 0.69 | G31: =C31*(1-D31) -> 0.2914 | H31: =C31*D31*(1-E31) -> 0.01767 | I31: =C31*D31*E31 -> 0.00093 | J31: =F31*$B$15+G31*$B$16+H31*$B$17+I31*$B$18 -> 2.8631 | K31: =J31*INDEX($B$5:$B$8,MATCH($A31,$A$5:$A$8,0)) -> 85.893
A32: 고급 | B32: 62 | C32: =MIN($B$23,MAX($B$22,($B32-INDEX($C$5:$C$8,MATCH($A32,$A$5:$A$8,0))-$B$21*0)/100)) -> 0.57 | D32: =MIN($B$23,MAX($B$22,($B32-INDEX($C$5:$C$8,MATCH($A32,$A$5:$A$8,0))-$B$21*1)/100)) -> 0.32 | E32: =MIN($B$23,MAX($B$22,($B32-INDEX($C$5:$C$8,MATCH($A32,$A$5:$A$8,0))-$B$21*2)/100)) -> 0.07 | F32: =1-C32 -> 0.43 | G32: =C32*(1-D32) -> 0.3876 | H32: =C32*D32*(1-E32) -> 0.169632 | I32: =C32*D32*E32 -> 0.012768 | J32: =F32*$B$15+G32*$B$16+H32*$B$17+I32*$B$18 -> 10.01056 | K32: =J32*INDEX($B$5:$B$8,MATCH($A32,$A$5:$A$8,0)) -> 300.3168
A33: 고급 | B33: 78 | C33: =MIN($B$23,MAX($B$22,($B33-INDEX($C$5:$C$8,MATCH($A33,$A$5:$A$8,0))-$B$21*0)/100)) -> 0.73 | D33: =MIN($B$23,MAX($B$22,($B33-INDEX($C$5:$C$8,MATCH($A33,$A$5:$A$8,0))-$B$21*1)/100)) -> 0.48 | E33: =MIN($B$23,MAX($B$22,($B33-INDEX($C$5:$C$8,MATCH($A33,$A$5:$A$8,0))-$B$21*2)/100)) -> 0.23 | F33: =1-C33 -> 0.27 | G33: =C33*(1-D33) -> 0.3796 | H33: =C33*D33*(1-E33) -> 0.269808 | I33: =C33*D33*E33 -> 0.080592 | J33: =F33*$B$15+G33*$B$16+H33*$B$17+I33*$B$18 -> 26.38064 | K33: =J33*INDEX($B$5:$B$8,MATCH($A33,$A$5:$A$8,0)) -> 791.4192
A34: 고급 | B34: 90 | C34: =MIN($B$23,MAX($B$22,($B34-INDEX($C$5:$C$8,MATCH($A34,$A$5:$A$8,0))-$B$21*0)/100)) -> 0.85 | D34: =MIN($B$23,MAX($B$22,($B34-INDEX($C$5:$C$8,MATCH($A34,$A$5:$A$8,0))-$B$21*1)/100)) -> 0.6 | E34: =MIN($B$23,MAX($B$22,($B34-INDEX($C$5:$C$8,MATCH($A34,$A$5:$A$8,0))-$B$21*2)/100)) -> 0.35 | F34: =1-C34 -> 0.15 | G34: =C34*(1-D34) -> 0.34 | H34: =C34*D34*(1-E34) -> 0.3315 | I34: =C34*D34*E34 -> 0.1785 | J34: =F34*$B$15+G34*$B$16+H34*$B$17+I34*$B$18 -> 47.495 | K34: =J34*INDEX($B$5:$B$8,MATCH($A34,$A$5:$A$8,0)) -> 1424.85
A35: 희귀 | B35: 36 | C35: =MIN($B$23,MAX($B$22,($B35-INDEX($C$5:$C$8,MATCH($A35,$A$5:$A$8,0))-$B$21*0)/100)) -> 0.26 | D35: =MIN($B$23,MAX($B$22,($B35-INDEX($C$5:$C$8,MATCH($A35,$A$5:$A$8,0))-$B$21*1)/100)) -> 0.05 | E35: =MIN($B$23,MAX($B$22,($B35-INDEX($C$5:$C$8,MATCH($A35,$A$5:$A$8,0))-$B$21*2)/100)) -> 0.05 | F35: =1-C35 -> 0.74 | G35: =C35*(1-D35) -> 0.247 | H35: =C35*D35*(1-E35) -> 0.01235 | I35: =C35*D35*E35 -> 0.00065 | J35: =F35*$B$15+G35*$B$16+H35*$B$17+I35*$B$18 -> 2.4755 | K35: =J35*INDEX($B$5:$B$8,MATCH($A35,$A$5:$A$8,0)) -> 371.325
A36: 희귀 | B36: 62 | C36: =MIN($B$23,MAX($B$22,($B36-INDEX($C$5:$C$8,MATCH($A36,$A$5:$A$8,0))-$B$21*0)/100)) -> 0.52 | D36: =MIN($B$23,MAX($B$22,($B36-INDEX($C$5:$C$8,MATCH($A36,$A$5:$A$8,0))-$B$21*1)/100)) -> 0.27 | E36: =MIN($B$23,MAX($B$22,($B36-INDEX($C$5:$C$8,MATCH($A36,$A$5:$A$8,0))-$B$21*2)/100)) -> 0.05 | F36: =1-C36 -> 0.48 | G36: =C36*(1-D36) -> 0.3796 | H36: =C36*D36*(1-E36) -> 0.13338 | I36: =C36*D36*E36 -> 0.00702 | J36: =F36*$B$15+G36*$B$16+H36*$B$17+I36*$B$18 -> 7.7834 | K36: =J36*INDEX($B$5:$B$8,MATCH($A36,$A$5:$A$8,0)) -> 1167.51
A37: 희귀 | B37: 78 | C37: =MIN($B$23,MAX($B$22,($B37-INDEX($C$5:$C$8,MATCH($A37,$A$5:$A$8,0))-$B$21*0)/100)) -> 0.68 | D37: =MIN($B$23,MAX($B$22,($B37-INDEX($C$5:$C$8,MATCH($A37,$A$5:$A$8,0))-$B$21*1)/100)) -> 0.43 | E37: =MIN($B$23,MAX($B$22,($B37-INDEX($C$5:$C$8,MATCH($A37,$A$5:$A$8,0))-$B$21*2)/100)) -> 0.18 | F37: =1-C37 -> 0.32 | G37: =C37*(1-D37) -> 0.3876 | H37: =C37*D37*(1-E37) -> 0.239768 | I37: =C37*D37*E37 -> 0.052632 | J37: =F37*$B$15+G37*$B$16+H37*$B$17+I37*$B$18 -> 19.97744 | K37: =J37*INDEX($B$5:$B$8,MATCH($A37,$A$5:$A$8,0)) -> 2996.616
A38: 희귀 | B38: 90 | C38: =MIN($B$23,MAX($B$22,($B38-INDEX($C$5:$C$8,MATCH($A38,$A$5:$A$8,0))-$B$21*0)/100)) -> 0.8 | D38: =MIN($B$23,MAX($B$22,($B38-INDEX($C$5:$C$8,MATCH($A38,$A$5:$A$8,0))-$B$21*1)/100)) -> 0.55 | E38: =MIN($B$23,MAX($B$22,($B38-INDEX($C$5:$C$8,MATCH($A38,$A$5:$A$8,0))-$B$21*2)/100)) -> 0.3 | F38: =1-C38 -> 0.2 | G38: =C38*(1-D38) -> 0.36 | H38: =C38*D38*(1-E38) -> 0.308 | I38: =C38*D38*E38 -> 0.132 | J38: =F38*$B$15+G38*$B$16+H38*$B$17+I38*$B$18 -> 37.64 | K38: =J38*INDEX($B$5:$B$8,MATCH($A38,$A$5:$A$8,0)) -> 5646
... A42: 전설 | B42: 90 | C42: =MIN($B$23,MAX($B$22,($B42-INDEX($C$5:$C$8,MATCH($A42,$A$5:$A$8,0))-$B$21*0)/100)) -> 0.75 | D42: =MIN($B$23,MAX($B$22,($B42-INDEX($C$5:$C$8,MATCH($A42,$A$5:$A$8,0))-$B$21*1)/100)) -> 0.5 | E42: =MIN($B$23,MAX($B$22,($B42-INDEX($C$5:$C$8,MATCH($A42,$A$5:$A$8,0))-$B$21*2)/100)) -> 0.25 | F42: =1-C42 -> 0.25 | G42: =C42*(1-D42) -> 0.375 | H42: =C42*D42*(1-E42) -> 0.28125 | I42: =C42*D42*E42 -> 0.09375 | J42: =F42*$B$15+G42*$B$16+H42*$B$17+I42*$B$18 -> 29.3125 | K42: =J42*INDEX($B$5:$B$8,MATCH($A42,$A$5:$A$8,0)) -> 29312.5
A44: 같은 작물 n개 중 가장 좋은 3개의 평균 품질: 3개 36 · 10개 62 · 30개 78 · 100개 89 (계획 §14)
A45: 도감: 도감 6개 요리를 제출하면 등록 (가방에서 빠짐). 같은 요리를 별이 더 높게 내면 갱신. 요리는 먹지 않음 (판매와 도감 제출만)

Sheet 요리 목록
A1: 요리 목록 (100개)
A2: 계획 §13. 재료는 작물만, 최대 3종류, 같은 재료는 3개까지. 등급 = 재료 중 가장 높은 작물 등급. 재료 이름은 작물 시트 이름과 같아야 해요 (확인 칸)
A4: # | B4: 등급 | C4: 요리 | D4: 재료 1 | E4: 개수 | F4: 재료 2 | G4: 개수 | H4: 재료 3 | I4: 개수 | J4: 재료 수 | K4: 원래 값 최소 | L4: 원래 값 최대 | M4: 3성 최대 값 | N4: 재료로 본 등급 | O4: 확인
A5: 1 | B5: 일반 | C5: 찐 감자 | D5: 감자 | E5: 3 | J5: =SUM(E5,G5,I5) -> 3 | K5: =ROUND(INDEX(요리·별!$B$5:$B$8,MATCH(B5,요리·별!$A$5:$A$8,0))*(1-요리·별!$B$11),0) -> 9 | L5: =ROUND(INDEX(요리·별!$B$5:$B$8,MATCH(B5,요리·별!$A$5:$A$8,0))*(1+요리·별!$B$11),0) -> 11 | M5: =L5*요리·별!$B$18 -> 2200 | N5: =IFERROR(INDEX({"일반","고급","희귀","전설"},MAX(IF(D5="",0,MATCH(INDEX(작물!$B$17:$B$71,MATCH(D5,작물!$C$17:$C$71,0)),{"일반","고급","희귀","전설"},0)),IF(F5="",0,MATCH(INDEX(작물!$B$17:$B$71,MATCH(F5,작물!$C$17:$C$71,0)),{"일반","고급","희귀","전설"},0)),IF(H5="",0,MATCH(INDEX(작물!$B$17:$B$71,MATCH(H5,작물!$C$17:$C$71,0)),{"일반","고급","희귀","전설"},0)))),"작물 이름 확인") -> 일반 | O5: =IF(N5="작물 이름 확인",N5,IF(MAX(E5,G5,I5)>3,"같은 재료 3개 넘음",IF(N5=B5,"OK","등급 다름"))) -> OK
A6: 2 | B6: 일반 | C6: 군고구마 | D6: 고구마 | E6: 3 | J6: =SUM(E6,G6,I6) -> 3 | K6: =ROUND(INDEX(요리·별!$B$5:$B$8,MATCH(B6,요리·별!$A$5:$A$8,0))*(1-요리·별!$B$11),0) -> 9 | L6: =ROUND(INDEX(요리·별!$B$5:$B$8,MATCH(B6,요리·별!$A$5:$A$8,0))*(1+요리·별!$B$11),0) -> 11 | M6: =L6*요리·별!$B$18 -> 2200 | N6: =IFERROR(INDEX({"일반","고급","희귀","전설"},MAX(IF(D6="",0,MATCH(INDEX(작물!$B$17:$B$71,MATCH(D6,작물!$C$17:$C$71,0)),{"일반","고급","희귀","전설"},0)),IF(F6="",0,MATCH(INDEX(작물!$B$17:$B$71,MATCH(F6,작물!$C$17:$C$71,0)),{"일반","고급","희귀","전설"},0)),IF(H6="",0,MATCH(INDEX(작물!$B$17:$B$71,MATCH(H6,작물!$C$17:$C$71,0)),{"일반","고급","희귀","전설"},0)))),"작물 이름 확인") -> 일반 | O6: =IF(N6="작물 이름 확인",N6,IF(MAX(E6,G6,I6)>3,"같은 재료 3개 넘음",IF(N6=B6,"OK","등급 다름"))) -> OK
A7: 3 | B7: 일반 | C7: 쌀밥 | D7: 벼 | E7: 3 | J7: =SUM(E7,G7,I7) -> 3 | K7: =ROUND(INDEX(요리·별!$B$5:$B$8,MATCH(B7,요리·별!$A$5:$A$8,0))*(1-요리·별!$B$11),0) -> 9 | L7: =ROUND(INDEX(요리·별!$B$5:$B$8,MATCH(B7,요리·별!$A$5:$A$8,0))*(1+요리·별!$B$11),0) -> 11 | M7: =L7*요리·별!$B$18 -> 2200 | N7: =IFERROR(INDEX({"일반","고급","희귀","전설"},MAX(IF(D7="",0,MATCH(INDEX(작물!$B$17:$B$71,MATCH(D7,작물!$C$17:$C$71,0)),{"일반","고급","희귀","전설"},0)),IF(F7="",0,MATCH(INDEX(작물!$B$17:$B$71,MATCH(F7,작물!$C$17:$C$71,0)),{"일반","고급","희귀","전설"},0)),IF(H7="",0,MATCH(INDEX(작물!$B$17:$B$71,MATCH(H7,작물!$C$17:$C$71,0)),{"일반","고급","희귀","전설"},0)))),"작물 이름 확인") -> 일반 | O7: =IF(N7="작물 이름 확인",N7,IF(MAX(E7,G7,I7)>3,"같은 재료 3개 넘음",IF(N7=B7,"OK","등급 다름"))) -> OK
A8: 4 | B8: 일반 | C8: 군옥수수 | D8: 옥수수 | E8: 3 | J8: =SUM(E8,G8,I8) -> 3 | K8: =ROUND(INDEX(요리·별!$B$5:$B$8,MATCH(B8,요리·별!$A$5:$A$8,0))*(1-요리·별!$B$11),0) -> 9 | L8: =ROUND(INDEX(요리·별!$B$5:$B$8,MATCH(B8,요리·별!$A$5:$A$8,0))*(1+요리·별!$B$11),0) -> 11 | M8: =L8*요리·별!$B$18 -> 2200 | N8: =IFERROR(INDEX({"일반","고급","희귀","전설"},MAX(IF(D8="",0,MATCH(INDEX(작물!$B$17:$B$71,MATCH(D8,작물!$C$17:$C$71,0)),{"일반","고급","희귀","전설"},0)),IF(F8="",0,MATCH(INDEX(작물!$B$17:$B$71,MATCH(F8,작물!$C$17:$C$71,0)),{"일반","고급","희귀","전설"},0)),IF(H8="",0,MATCH(INDEX(작물!$B$17:$B$71,MATCH(H8,작물!$C$17:$C$71,0)),{"일반","고급","희귀","전설"},0)))),"작물 이름 확인") -> 일반 | O8: =IF(N8="작물 이름 확인",N8,IF(MAX(E8,G8,I8)>3,"같은 재료 3개 넘음",IF(N8=B8,"OK","등급 다름"))) -> OK
A9: 5 | B9: 일반 | C9: 식빵 | D9: 밀 | E9: 3 | J9: =SUM(E9,G9,I9) -> 3 | K9: =ROUND(INDEX(요리·별!$B$5:$B$8,MATCH(B9,요리·별!$A$5:$A$8,0))*(1-요리·별!$B$11),0) -> 9 | L9: =ROUND(INDEX(요리·별!$B$5:$B$8,MATCH(B9,요리·별!$A$5:$A$8,0))*(1+요리·별!$B$11),0) -> 11 | M9: =L9*요리·별!$B$18 -> 2200 | N9: =IFERROR(INDEX({"일반","고급","희귀","전설"},MAX(IF(D9="",0,MATCH(INDEX(작물!$B$17:$B$71,MATCH(D9,작물!$C$17:$C$71,0)),{"일반","고급","희귀","전설"},0)),IF(F9="",0,MATCH(INDEX(작물!$B$17:$B$71,MATCH(F9,작물!$C$17:$C$71,0)),{"일반","고급","희귀","전설"},0)),IF(H9="",0,MATCH(INDEX(작물!$B$17:$B$71,MATCH(H9,작물!$C$17:$C$71,0)),{"일반","고급","희귀","전설"},0)))),"작물 이름 확인") -> 일반 | O9: =IF(N9="작물 이름 확인",N9,IF(MAX(E9,G9,I9)>3,"같은 재료 3개 넘음",IF(N9=B9,"OK","등급 다름"))) -> OK
A10: 6 | B10: 일반 | C10: 당근 주스 | D10: 당근 | E10: 3 | J10: =SUM(E10,G10,I10) -> 3 | K10: =ROUND(INDEX(요리·별!$B$5:$B$8,MATCH(B10,요리·별!$A$5:$A$8,0))*(1-요리·별!$B$11),0) -> 9 | L10: =ROUND(INDEX(요리·별!$B$5:$B$8,MATCH(B10,요리·별!$A$5:$A$8,0))*(1+요리·별!$B$11),0) -> 11 | M10: =L10*요리·별!$B$18 -> 2200 | N10: =IFERROR(INDEX({"일반","고급","희귀","전설"},MAX(IF(D10="",0,MATCH(INDEX(작물!$B$17:$B$71,MATCH(D10,작물!$C$17:$C$71,0)),{"일반","고급","희귀","전설"},0)),IF(F10="",0,MATCH(INDEX(작물!$B$17:$B$71,MATCH(F10,작물!$C$17:$C$71,0)),{"일반","고급","희귀","전설"},0)),IF(H10="",0,MATCH(INDEX(작물!$B$17:$B$71,MATCH(H10,작물!$C$17:$C$71,0)),{"일반","고급","희귀","전설"},0)))),"작물 이름 확인") -> 일반 | O10: =IF(N10="작물 이름 확인",N10,IF(MAX(E10,G10,I10)>3,"같은 재료 3개 넘음",IF(N10=B10,"OK","등급 다름"))) -> OK
A11: 7 | B11: 일반 | C11: 감자전 | D11: 감자 | E11: 3 | F11: 양파 | G11: 1 | J11: =SUM(E11,G11,I11) -> 4 | K11: =ROUND(INDEX(요리·별!$B$5:$B$8,MATCH(B11,요리·별!$A$5:$A$8,0))*(1-요리·별!$B$11),0) -> 9 | L11: =ROUND(INDEX(요리·별!$B$5:$B$8,MATCH(B11,요리·별!$A$5:$A$8,0))*(1+요리·별!$B$11),0) -> 11 | M11: =L11*요리·별!$B$18 -> 2200 | N11: =IFERROR(INDEX({"일반","고급","희귀","전설"},MAX(IF(D11="",0,MATCH(INDEX(작물!$B$17:$B$71,MATCH(D11,작물!$C$17:$C$71,0)),{"일반","고급","희귀","전설"},0)),IF(F11="",0,MATCH(INDEX(작물!$B$17:$B$71,MATCH(F11,작물!$C$17:$C$71,0)),{"일반","고급","희귀","전설"},0)),IF(H11="",0,MATCH(INDEX(작물!$B$17:$B$71,MATCH(H11,작물!$C$17:$C$71,0)),{"일반","고급","희귀","전설"},0)))),"작물 이름 확인") -> 일반 | O11: =IF(N11="작물 이름 확인",N11,IF(MAX(E11,G11,I11)>3,"같은 재료 3개 넘음",IF(N11=B11,"OK","등급 다름"))) -> OK
A12: 8 | B12: 일반 | C12: 감자 수프 | D12: 감자 | E12: 2 | F12: 양파 | G12: 1 | H12: 대파 | I12: 1 | J12: =SUM(E12,G12,I12) -> 4 | K12: =ROUND(INDEX(요리·별!$B$5:$B$8,MATCH(B12,요리·별!$A$5:$A$8,0))*(1-요리·별!$B$11),0) -> 9 | L12: =ROUND(INDEX(요리·별!$B$5:$B$8,MATCH(B12,요리·별!$A$5:$A$8,0))*(1+요리·별!$B$11),0) -> 11 | M12: =L12*요리·별!$B$18 -> 2200 | N12: =IFERROR(INDEX({"일반","고급","희귀","전설"},MAX(IF(D12="",0,MATCH(INDEX(작물!$B$17:$B$71,MATCH(D12,작물!$C$17:$C$71,0)),{"일반","고급","희귀","전설"},0)),IF(F12="",0,MATCH(INDEX(작물!$B$17:$B$71,MATCH(F12,작물!$C$17:$C$71,0)),{"일반","고급","희귀","전설"},0)),IF(H12="",0,MATCH(INDEX(작물!$B$17:$B$71,MATCH(H12,작물!$C$17:$C$71,0)),{"일반","고급","희귀","전설"},0)))),"작물 이름 확인") -> 일반 | O12: =IF(N12="작물 이름 확인",N12,IF(MAX(E12,G12,I12)>3,"같은 재료 3개 넘음",IF(N12=B12,"OK","등급 다름"))) -> OK
A13: 9 | B13: 일반 | C13: 감자 샐러드 | D13: 감자 | E13: 2 | F13: 당근 | G13: 1 | H13: 오이 | I13: 1 | J13: =SUM(E13,G13,I13) -> 4 | K13: =ROUND(INDEX(요리·별!$B$5:$B$8,MATCH(B13,요리·별!$A$5:$A$8,0))*(1-요리·별!$B$11),0) -> 9 | L13: =ROUND(INDEX(요리·별!$B$5:$B$8,MATCH(B13,요리·별!$A$5:$A$8,0))*(1+요리·별!$B$11),0) -> 11 | M13: =L13*요리·별!$B$18 -> 2200 | N13: =IFERROR(INDEX({"일반","고급","희귀","전설"},MAX(IF(D13="",0,MATCH(INDEX(작물!$B$17:$B$71,MATCH(D13,작물!$C$17:$C$71,0)),{"일반","고급","희귀","전설"},0)),IF(F13="",0,MATCH(INDEX(작물!$B$17:$B$71,MATCH(F13,작물!$C$17:$C$71,0)),{"일반","고급","희귀","전설"},0)),IF(H13="",0,MATCH(INDEX(작물!$B$17:$B$71,MATCH(H13,작물!$C$17:$C$71,0)),{"일반","고급","희귀","전설"},0)))),"작물 이름 확인") -> 일반 | O13: =IF(N13="작물 이름 확인",N13,IF(MAX(E13,G13,I13)>3,"같은 재료 3개 넘음",IF(N13=B13,"OK","등급 다름"))) -> OK
A14: 10 | B14: 일반 | C14: 고구마빵 | D14: 고구마 | E14: 2 | F14: 밀 | G14: 2 | J14: =SUM(E14,G14,I14) -> 4 | K14: =ROUND(INDEX(요리·별!$B$5:$B$8,MATCH(B14,요리·별!$A$5:$A$8,0))*(1-요리·별!$B$11),0) -> 9 | L14: =ROUND(INDEX(요리·별!$B$5:$B$8,MATCH(B14,요리·별!$A$5:$A$8,0))*(1+요리·별!$B$11),0) -> 11 | M14: =L14*요리·별!$B$18 -> 2200 | N14: =IFERROR(INDEX({"일반","고급","희귀","전설"},MAX(IF(D14="",0,MATCH(INDEX(작물!$B$17:$B$71,MATCH(D14,작물!$C$17:$C$71,0)),{"일반","고급","희귀","전설"},0)),IF(F14="",0,MATCH(INDEX(작물!$B$17:$B$71,MATCH(F14,작물!$C$17:$C$71,0)),{"일반","고급","희귀","전설"},0)),IF(H14="",0,MATCH(INDEX(작물!$B$17:$B$71,MATCH(H14,작물!$C$17:$C$71,0)),{"일반","고급","희귀","전설"},0)))),"작물 이름 확인") -> 일반 | O14: =IF(N14="작물 이름 확인",N14,IF(MAX(E14,G14,I14)>3,"같은 재료 3개 넘음",IF(N14=B14,"OK","등급 다름"))) -> OK
A15: 11 | B15: 일반 | C15: 잡채 | D15: 고구마 | E15: 2 | F15: 시금치 | G15: 1 | H15: 당근 | I15: 1 | J15: =SUM(E15,G15,I15) -> 4 | K15: =ROUND(INDEX(요리·별!$B$5:$B$8,MATCH(B15,요리·별!$A$5:$A$8,0))*(1-요리·별!$B$11),0) -> 9 | L15: =ROUND(INDEX(요리·별!$B$5:$B$8,MATCH(B15,요리·별!$A$5:$A$8,0))*(1+요리·별!$B$11),0) -> 11 | M15: =L15*요리·별!$B$18 -> 2200 | N15: =IFERROR(INDEX({"일반","고급","희귀","전설"},MAX(IF(D15="",0,MATCH(INDEX(작물!$B$17:$B$71,MATCH(D15,작물!$C$17:$C$71,0)),{"일반","고급","희귀","전설"},0)),IF(F15="",0,MATCH(INDEX(작물!$B$17:$B$71,MATCH(F15,작물!$C$17:$C$71,0)),{"일반","고급","희귀","전설"},0)),IF(H15="",0,MATCH(INDEX(작물!$B$17:$B$71,MATCH(H15,작물!$C$17:$C$71,0)),{"일반","고급","희귀","전설"},0)))),"작물 이름 확인") -> 일반 | O15: =IF(N15="작물 이름 확인",N15,IF(MAX(E15,G15,I15)>3,"같은 재료 3개 넘음",IF(N15=B15,"OK","등급 다름"))) -> OK
A16: 12 | B16: 일반 | C16: 배추김치 | D16: 배추 | E16: 3 | F16: 고추 | G16: 2 | H16: 마늘 | I16: 2 | J16: =SUM(E16,G16,I16) -> 7 | K16: =ROUND(INDEX(요리·별!$B$5:$B$8,MATCH(B16,요리·별!$A$5:$A$8,0))*(1-요리·별!$B$11),0) -> 9 | L16: =ROUND(INDEX(요리·별!$B$5:$B$8,MATCH(B16,요리·별!$A$5:$A$8,0))*(1+요리·별!$B$11),0) -> 11 | M16: =L16*요리·별!$B$18 -> 2200 | N16: =IFERROR(INDEX({"일반","고급","희귀","전설"},MAX(IF(D16="",0,MATCH(INDEX(작물!$B$17:$B$71,MATCH(D16,작물!$C$17:$C$71,0)),{"일반","고급","희귀","전설"},0)),IF(F16="",0,MATCH(INDEX(작물!$B$17:$B$71,MATCH(F16,작물!$C$17:$C$71,0)),{"일반","고급","희귀","전설"},0)),IF(H16="",0,MATCH(INDEX(작물!$B$17:$B$71,MATCH(H16,작물!$C$17:$C$71,0)),{"일반","고급","희귀","전설"},0)))),"작물 이름 확인") -> 일반 | O16: =IF(N16="작물 이름 확인",N16,IF(MAX(E16,G16,I16)>3,"같은 재료 3개 넘음",IF(N16=B16,"OK","등급 다름"))) -> OK
A17: 13 | B17: 일반 | C17: 깍두기 | D17: 무 | E17: 3 | F17: 고추 | G17: 2 | H17: 마늘 | I17: 1 | J17: =SUM(E17,G17,I17) -> 6 | K17: =ROUND(INDEX(요리·별!$B$5:$B$8,MATCH(B17,요리·별!$A$5:$A$8,0))*(1-요리·별!$B$11),0) -> 9 | L17: =ROUND(INDEX(요리·별!$B$5:$B$8,MATCH(B17,요리·별!$A$5:$A$8,0))*(1+요리·별!$B$11),0) -> 11 | M17: =L17*요리·별!$B$18 -> 2200 | N17: =IFERROR(INDEX({"일반","고급","희귀","전설"},MAX(IF(D17="",0,MATCH(INDEX(작물!$B$17:$B$71,MATCH(D17,작물!$C$17:$C$71,0)),{"일반","고급","희귀","전설"},0)),IF(F17="",0,MATCH(INDEX(작물!$B$17:$B$71,MATCH(F17,작물!$C$17:$C$71,0)),{"일반","고급","희귀","전설"},0)),IF(H17="",0,MATCH(INDEX(작물!$B$17:$B$71,MATCH(H17,작물!$C$17:$C$71,0)),{"일반","고급","희귀","전설"},0)))),"작물 이름 확인") -> 일반 | O17: =IF(N17="작물 이름 확인",N17,IF(MAX(E17,G17,I17)>3,"같은 재료 3개 넘음",IF(N17=B17,"OK","등급 다름"))) -> OK
A18: 14 | B18: 일반 | C18: 오이소박이 | D18: 오이 | E18: 3 | F18: 고추 | G18: 1 | H18: 대파 | I18: 1 | J18: =SUM(E18,G18,I18) -> 5 | K18: =ROUND(INDEX(요리·별!$B$5:$B$8,MATCH(B18,요리·별!$A$5:$A$8,0))*(1-요리·별!$B$11),0) -> 9 | L18: =ROUND(INDEX(요리·별!$B$5:$B$8,MATCH(B18,요리·별!$A$5:$A$8,0))*(1+요리·별!$B$11),0) -> 11 | M18: =L18*요리·별!$B$18 -> 2200 | N18: =IFERROR(INDEX({"일반","고급","희귀","전설"},MAX(IF(D18="",0,MATCH(INDEX(작물!$B$17:$B$71,MATCH(D18,작물!$C$17:$C$71,0)),{"일반","고급","희귀","전설"},0)),IF(F18="",0,MATCH(INDEX(작물!$B$17:$B$71,MATCH(F18,작물!$C$17:$C$71,0)),{"일반","고급","희귀","전설"},0)),IF(H18="",0,MATCH(INDEX(작물!$B$17:$B$71,MATCH(H18,작물!$C$17:$C$71,0)),{"일반","고급","희귀","전설"},0)))),"작물 이름 확인") -> 일반 | O18: =IF(N18="작물 이름 확인",N18,IF(MAX(E18,G18,I18)>3,"같은 재료 3개 넘음",IF(N18=B18,"OK","등급 다름"))) -> OK
A19: 15 | B19: 일반 | C19: 오이 냉국 | D19: 오이 | E19: 2 | F19: 양파 | G19: 1 | H19: 고추 | I19: 1 | J19: =SUM(E19,G19,I19) -> 4 | K19: =ROUND(INDEX(요리·별!$B$5:$B$8,MATCH(B19,요리·별!$A$5:$A$8,0))*(1-요리·별!$B$11),0) -> 9 | L19: =ROUND(INDEX(요리·별!$B$5:$B$8,MATCH(B19,요리·별!$A$5:$A$8,0))*(1+요리·별!$B$11),0) -> 11 | M19: =L19*요리·별!$B$18 -> 2200 | N19: =IFERROR(INDEX({"일반","고급","희귀","전설"},MAX(IF(D19="",0,MATCH(INDEX(작물!$B$17:$B$71,MATCH(D19,작물!$C$17:$C$71,0)),{"일반","고급","희귀","전설"},0)),IF(F19="",0,MATCH(INDEX(작물!$B$17:$B$71,MATCH(F19,작물!$C$17:$C$71,0)),{"일반","고급","희귀","전설"},0)),IF(H19="",0,MATCH(INDEX(작물!$B$17:$B$71,MATCH(H19,작물!$C$17:$C$71,0)),{"일반","고급","희귀","전설"},0)))),"작물 이름 확인") -> 일반 | O19: =IF(N19="작물 이름 확인",N19,IF(MAX(E19,G19,I19)>3,"같은 재료 3개 넘음",IF(N19=B19,"OK","등급 다름"))) -> OK
A20: 16 | B20: 일반 | C20: 뭇국 | D20: 무 | E20: 2 | F20: 대파 | G20: 1 | H20: 마늘 | I20: 1 | J20: =SUM(E20,G20,I20) -> 4 | K20: =ROUND(INDEX(요리·별!$B$5:$B$8,MATCH(B20,요리·별!$A$5:$A$8,0))*(1-요리·별!$B$11),0) -> 9 | L20: =ROUND(INDEX(요리·별!$B$5:$B$8,MATCH(B20,요리·별!$A$5:$A$8,0))*(1+요리·별!$B$11),0) -> 11 | M20: =L20*요리·별!$B$18 -> 2200 | N20: =IFERROR(INDEX({"일반","고급","희귀","전설"},MAX(IF(D20="",0,MATCH(INDEX(작물!$B$17:$B$71,MATCH(D20,작물!$C$17:$C$71,0)),{"일반","고급","희귀","전설"},0)),IF(F20="",0,MATCH(INDEX(작물!$B$17:$B$71,MATCH(F20,작물!$C$17:$C$71,0)),{"일반","고급","희귀","전설"},0)),IF(H20="",0,MATCH(INDEX(작물!$B$17:$B$71,MATCH(H20,작물!$C$17:$C$71,0)),{"일반","고급","희귀","전설"},0)))),"작물 이름 확인") -> 일반 | O20: =IF(N20="작물 이름 확인",N20,IF(MAX(E20,G20,I20)>3,"같은 재료 3개 넘음",IF(N20=B20,"OK","등급 다름"))) -> OK
A21: 17 | B21: 일반 | C21: 시금치나물 | D21: 시금치 | E21: 3 | F21: 마늘 | G21: 1 | J21: =SUM(E21,G21,I21) -> 4 | K21: =ROUND(INDEX(요리·별!$B$5:$B$8,MATCH(B21,요리·별!$A$5:$A$8,0))*(1-요리·별!$B$11),0) -> 9 | L21: =ROUND(INDEX(요리·별!$B$5:$B$8,MATCH(B21,요리·별!$A$5:$A$8,0))*(1+요리·별!$B$11),0) -> 11 | M21: =L21*요리·별!$B$18 -> 2200 | N21: =IFERROR(INDEX({"일반","고급","희귀","전설"},MAX(IF(D21="",0,MATCH(INDEX(작물!$B$17:$B$71,MATCH(D21,작물!$C$17:$C$71,0)),{"일반","고급","희귀","전설"},0)),IF(F21="",0,MATCH(INDEX(작물!$B$17:$B$71,MATCH(F21,작물!$C$17:$C$71,0)),{"일반","고급","희귀","전설"},0)),IF(H21="",0,MATCH(INDEX(작물!$B$17:$B$71,MATCH(H21,작물!$C$17:$C$71,0)),{"일반","고급","희귀","전설"},0)))),"작물 이름 확인") -> 일반 | O21: =IF(N21="작물 이름 확인",N21,IF(MAX(E21,G21,I21)>3,"같은 재료 3개 넘음",IF(N21=B21,"OK","등급 다름"))) -> OK
A22: 18 | B22: 일반 | C22: 상추 겉절이 | D22: 상추 | E22: 3 | F22: 고추 | G22: 1 | H22: 대파 | I22: 1 | J22: =SUM(E22,G22,I22) -> 5 | K22: =ROUND(INDEX(요리·별!$B$5:$B$8,MATCH(B22,요리·별!$A$5:$A$8,0))*(1-요리·별!$B$11),0) -> 9 | L22: =ROUND(INDEX(요리·별!$B$5:$B$8,MATCH(B22,요리·별!$A$5:$A$8,0))*(1+요리·별!$B$11),0) -> 11 | M22: =L22*요리·별!$B$18 -> 2200 | N22: =IFERROR(INDEX({"일반","고급","희귀","전설"},MAX(IF(D22="",0,MATCH(INDEX(작물!$B$17:$B$71,MATCH(D22,작물!$C$17:$C$71,0)),{"일반","고급","희귀","전설"},0)),IF(F22="",0,MATCH(INDEX(작물!$B$17:$B$71,MATCH(F22,작물!$C$17:$C$71,0)),{"일반","고급","희귀","전설"},0)),IF(H22="",0,MATCH(INDEX(작물!$B$17:$B$71,MATCH(H22,작물!$C$17:$C$71,0)),{"일반","고급","희귀","전설"},0)))),"작물 이름 확인") -> 일반 | O22: =IF(N22="작물 이름 확인",N22,IF(MAX(E22,G22,I22)>3,"같은 재료 3개 넘음",IF(N22=B22,"OK","등급 다름"))) -> OK
A23: 19 | B23: 일반 | C23: 상추쌈밥 | D23: 상추 | E23: 2 | F23: 벼 | G23: 2 | H23: 콩 | I23: 1 | J23: =SUM(E23,G23,I23) -> 5 | K23: =ROUND(INDEX(요리·별!$B$5:$B$8,MATCH(B23,요리·별!$A$5:$A$8,0))*(1-요리·별!$B$11),0) -> 9 | L23: =ROUND(INDEX(요리·별!$B$5:$B$8,MATCH(B23,요리·별!$A$5:$A$8,0))*(1+요리·별!$B$11),0) -> 11 | M23: =L23*요리·별!$B$18 -> 2200 | N23: =IFERROR(INDEX({"일반","고급","희귀","전설"},MAX(IF(D23="",0,MATCH(INDEX(작물!$B$17:$B$71,MATCH(D23,작물!$C$17:$C$71,0)),{"일반","고급","희귀","전설"},0)),IF(F23="",0,MATCH(INDEX(작물!$B$17:$B$71,MATCH(F23,작물!$C$17:$C$71,0)),{"일반","고급","희귀","전설"},0)),IF(H23="",0,MATCH(INDEX(작물!$B$17:$B$71,MATCH(H23,작물!$C$17:$C$71,0)),{"일반","고급","희귀","전설"},0)))),"작물 이름 확인") -> 일반 | O23: =IF(N23="작물 이름 확인",N23,IF(MAX(E23,G23,I23)>3,"같은 재료 3개 넘음",IF(N23=B23,"OK","등급 다름"))) -> OK
A24: 20 | B24: 일반 | C24: 양배추 샐러드 | D24: 양배추 | E24: 2 | F24: 당근 | G24: 1 | H24: 오이 | I24: 1 | J24: =SUM(E24,G24,I24) -> 4 | K24: =ROUND(INDEX(요리·별!$B$5:$B$8,MATCH(B24,요리·별!$A$5:$A$8,0))*(1-요리·별!$B$11),0) -> 9 | L24: =ROUND(INDEX(요리·별!$B$5:$B$8,MATCH(B24,요리·별!$A$5:$A$8,0))*(1+요리·별!$B$11),0) -> 11 | M24: =L24*요리·별!$B$18 -> 2200 | N24: =IFERROR(INDEX({"일반","고급","희귀","전설"},MAX(IF(D24="",0,MATCH(INDEX(작물!$B$17:$B$71,MATCH(D24,작물!$C$17:$C$71,0)),{"일반","고급","희귀","전설"},0)),IF(F24="",0,MATCH(INDEX(작물!$B$17:$B$71,MATCH(F24,작물!$C$17:$C$71,0)),{"일반","고급","희귀","전설"},0)),IF(H24="",0,MATCH(INDEX(작물!$B$17:$B$71,MATCH(H24,작물!$C$17:$C$71,0)),{"일반","고급","희귀","전설"},0)))),"작물 이름 확인") -> 일반 | O24: =IF(N24="작물 이름 확인",N24,IF(MAX(E24,G24,I24)>3,"같은 재료 3개 넘음",IF(N24=B24,"OK","등급 다름"))) -> OK
A25: 21 | B25: 일반 | C25: 양배추 롤 | D25: 양배추 | E25: 3 | F25: 벼 | G25: 1 | H25: 토마토 | I25: 1 | J25: =SUM(E25,G25,I25) -> 5 | K25: =ROUND(INDEX(요리·별!$B$5:$B$8,MATCH(B25,요리·별!$A$5:$A$8,0))*(1-요리·별!$B$11),0) -> 9 | L25: =ROUND(INDEX(요리·별!$B$5:$B$8,MATCH(B25,요리·별!$A$5:$A$8,0))*(1+요리·별!$B$11),0) -> 11 | M25: =L25*요리·별!$B$18 -> 2200 | N25: =IFERROR(INDEX({"일반","고급","희귀","전설"},MAX(IF(D25="",0,MATCH(INDEX(작물!$B$17:$B$71,MATCH(D25,작물!$C$17:$C$71,0)),{"일반","고급","희귀","전설"},0)),IF(F25="",0,MATCH(INDEX(작물!$B$17:$B$71,MATCH(F25,작물!$C$17:$C$71,0)),{"일반","고급","희귀","전설"},0)),IF(H25="",0,MATCH(INDEX(작물!$B$17:$B$71,MATCH(H25,작물!$C$17:$C$71,0)),{"일반","고급","희귀","전설"},0)))),"작물 이름 확인") -> 일반 | O25: =IF(N25="작물 이름 확인",N25,IF(MAX(E25,G25,I25)>3,"같은 재료 3개 넘음",IF(N25=B25,"OK","등급 다름"))) -> OK
A26: 22 | B26: 일반 | C26: 가지볶음 | D26: 가지 | E26: 3 | F26: 마늘 | G26: 1 | J26: =SUM(E26,G26,I26) -> 4 | K26: =ROUND(INDEX(요리·별!$B$5:$B$8,MATCH(B26,요리·별!$A$5:$A$8,0))*(1-요리·별!$B$11),0) -> 9 | L26: =ROUND(INDEX(요리·별!$B$5:$B$8,MATCH(B26,요리·별!$A$5:$A$8,0))*(1+요리·별!$B$11),0) -> 11 | M26: =L26*요리·별!$B$18 -> 2200 | N26: =IFERROR(INDEX({"일반","고급","희귀","전설"},MAX(IF(D26="",0,MATCH(INDEX(작물!$B$17:$B$71,MATCH(D26,작물!$C$17:$C$71,0)),{"일반","고급","희귀","전설"},0)),IF(F26="",0,MATCH(INDEX(작물!$B$17:$B$71,MATCH(F26,작물!$C$17:$C$71,0)),{"일반","고급","희귀","전설"},0)),IF(H26="",0,MATCH(INDEX(작물!$B$17:$B$71,MATCH(H26,작물!$C$17:$C$71,0)),{"일반","고급","희귀","전설"},0)))),"작물 이름 확인") -> 일반 | O26: =IF(N26="작물 이름 확인",N26,IF(MAX(E26,G26,I26)>3,"같은 재료 3개 넘음",IF(N26=B26,"OK","등급 다름"))) -> OK
A27: 23 | B27: 일반 | C27: 라따뚜이 | D27: 가지 | E27: 1 | F27: 애호박 | G27: 1 | H27: 토마토 | I27: 1 | J27: =SUM(E27,G27,I27) -> 3 | K27: =ROUND(INDEX(요리·별!$B$5:$B$8,MATCH(B27,요리·별!$A$5:$A$8,0))*(1-요리·별!$B$11),0) -> 9 | L27: =ROUND(INDEX(요리·별!$B$5:$B$8,MATCH(B27,요리·별!$A$5:$A$8,0))*(1+요리·별!$B$11),0) -> 11 | M27: =L27*요리·별!$B$18 -> 2200 | N27: =IFERROR(INDEX({"일반","고급","희귀","전설"},MAX(IF(D27="",0,MATCH(INDEX(작물!$B$17:$B$71,MATCH(D27,작물!$C$17:$C$71,0)),{"일반","고급","희귀","전설"},0)),IF(F27="",0,MATCH(INDEX(작물!$B$17:$B$71,MATCH(F27,작물!$C$17:$C$71,0)),{"일반","고급","희귀","전설"},0)),IF(H27="",0,MATCH(INDEX(작물!$B$17:$B$71,MATCH(H27,작물!$C$17:$C$71,0)),{"일반","고급","희귀","전설"},0)))),"작물 이름 확인") -> 일반 | O27: =IF(N27="작물 이름 확인",N27,IF(MAX(E27,G27,I27)>3,"같은 재료 3개 넘음",IF(N27=B27,"OK","등급 다름"))) -> OK
A28: 24 | B28: 일반 | C28: 애호박전 | D28: 애호박 | E28: 2 | F28: 밀 | G28: 1 | J28: =SUM(E28,G28,I28) -> 3 | K28: =ROUND(INDEX(요리·별!$B$5:$B$8,MATCH(B28,요리·별!$A$5:$A$8,0))*(1-요리·별!$B$11),0) -> 9 | L28: =ROUND(INDEX(요리·별!$B$5:$B$8,MATCH(B28,요리·별!$A$5:$A$8,0))*(1+요리·별!$B$11),0) -> 11 | M28: =L28*요리·별!$B$18 -> 2200 | N28: =IFERROR(INDEX({"일반","고급","희귀","전설"},MAX(IF(D28="",0,MATCH(INDEX(작물!$B$17:$B$71,MATCH(D28,작물!$C$17:$C$71,0)),{"일반","고급","희귀","전설"},0)),IF(F28="",0,MATCH(INDEX(작물!$B$17:$B$71,MATCH(F28,작물!$C$17:$C$71,0)),{"일반","고급","희귀","전설"},0)),IF(H28="",0,MATCH(INDEX(작물!$B$17:$B$71,MATCH(H28,작물!$C$17:$C$71,0)),{"일반","고급","희귀","전설"},0)))),"작물 이름 확인") -> 일반 | O28: =IF(N28="작물 이름 확인",N28,IF(MAX(E28,G28,I28)>3,"같은 재료 3개 넘음",IF(N28=B28,"OK","등급 다름"))) -> OK
